<?xml version="1.0" ?>
<robot name="stand_chest" xmlns:xacro="http://www.ros.org/wiki/xacro">

<!-- <xacro:include filename="$(find stand_chest_description)/urdf/materials.xacro" />
<xacro:include filename="$(find stand_chest_description)/urdf/stand_chest.trans" /> -->
<!-- <xacro:include filename="$(find stand_chest_description)/urdf/stand_chest.gazebo" /> -->

  <material name="silver">
    <color rgba="0.700 0.700 0.700 1.000"/>
  </material>

  <xacro:macro name="load_stand_chest_urdf" params="prefix parent">

    <!-- Make sure the parent of this is the {parent} arg -->
    <joint name="${prefix}stand_joint" type="fixed">
      <origin xyz="-0.1 0.0 0.357425" rpy="0 0 0"/>
      <parent link="${parent}"/>
      <child link="${prefix}stand"/>
    </joint>

    <!-- We need to rename everything here to now just allow it allow there to be a torso -->
    <joint name="${prefix}chest_joint" type="prismatic">
      <!-- <origin xyz="-0.082038 0.000502 0.303534" rpy="0 0 0"/> -->
      <origin xyz="-0.082038 0.000502 0.303534" rpy="0 0 0"/>
      <parent link="${prefix}stand"/>
      <child link="${prefix}chest"/>
      <axis xyz="0.0 0.0 1.0"/>
      <limit upper="0.47" lower="0.00" effort="1000000" velocity="0.5"/>
    </joint>

    <!-- <joint name="Slider 125" type="prismatic">
      <origin xyz="-0.082038 0.000502 0.303534" rpy="0 0 0"/>
      <parent link="base_link"/>
      <child link="chest_1"/>
      <axis xyz="0.0 -0.0 -1.0"/>
      <limit upper="0.0" lower="-0.47" effort="100" velocity="100"/>
    </joint> -->

    <joint name="right_mounting_plate_joint" type="fixed">
      <origin xyz="0.162 -0.08192 0.267206" rpy="0 0 0"/>
      <parent link="${prefix}chest"/>
      <child link="${prefix}right_mounting_plate"/>
    </joint>

    <joint name="left_mounting_plate_joint" type="fixed">
      <origin xyz="0.162 0.08192 0.267206" rpy="0 0 0"/>
      <parent link="${prefix}chest"/>
      <child link="${prefix}left_mounting_plate"/>
    </joint>

    <!-- <link name="${prefix}stand">
      <inertial>
        <origin xyz="-0.037004070310384385 -0.00020044152592137615 0.5753345004257665" rpy="0 0 0"/>
        <mass value="33.868854678471465"/>
        <inertia ixx="6.060039" iyy="5.972007" izz="0.308603" ixy="-0.001526" iyz="0.007953" ixz="0.121063"/>
      </inertial>
      <visual>
        <origin xyz="0 0 0" rpy="0 0 0"/>
        <geometry>
          <mesh filename="package://gopher_description/stand_chest_description/meshes/base_link.stl" scale="0.001 0.001 0.001"/>
        </geometry>
        <material name="silver"/>
      </visual>
      <collision>
        <origin xyz="0 0 0" rpy="0 0 0"/>
        <geometry>
          <mesh filename="package://gopher_description/stand_chest_description/meshes/base_link.stl" scale="0.001 0.001 0.001"/>
        </geometry>
      </collision>
    </link> -->

    <link name="${prefix}stand">
      <inertial>
        <origin xyz="-0.037004058441535335 -0.00020043772780423342 0.5753345042683139" rpy="0 0 0"/>
        <mass value="33.86884985630993"/>
        <inertia ixx="6.060038" iyy="5.972006" izz="0.308603" ixy="-0.001526" iyz="0.007953" ixz="0.121063"/>
      </inertial>
      <visual>
        <origin xyz="0 0 0" rpy="0 0 0"/>
        <geometry>
          <!-- <mesh filename="package://stand_chest_description/meshes/base_link.stl" scale="0.001 0.001 0.001"/> -->
          <mesh filename="package://gopher_description/stand_chest_description/meshes/base.stl"/>
        </geometry>
        <material name="silver"/>
      </visual>
      <collision>
        <origin xyz="0 0 0" rpy="0 0 0"/>
        <geometry>
          <!-- <mesh filename="package://stand_chest_description/meshes/base_link.stl" scale="0.001 0.001 0.001"/> -->
          <mesh filename="package://gopher_description/stand_chest_description/meshes/base.stl"/>
        </geometry>
      </collision>
    </link>


    <!-- <link name="${prefix}chest">
      <inertial>
        <origin xyz="0.10867723103887933 -2.454320478433963e-05 0.21808816300602257" rpy="0 0 0"/>
        <mass value="17.059360311650657"/>
        <inertia ixx="0.33354" iyy="0.300823" izz="0.167767" ixy="-2.1e-05" iyz="-0.010615" ixz="0.035724"/>
      </inertial>
      <visual>
        <origin xyz="0.082038 -0.000502 -0.303534" rpy="0 0 0"/>
        <geometry>
          <mesh filename="package://gopher_description/stand_chest_description/meshes/chest.stl" "/>
        </geometry>
        <material name="silver"/>
      </visual>
      <collision>
        <origin xyz="0.082038 -0.000502 -0.303534" rpy="0 0 0"/>
        <geometry>
          <mesh filename="package://gopher_description/stand_chest_description/meshes/chest.stl" "/>
        </geometry>
      </collision>
    </link> -->

    <link name="${prefix}chest">
      <inertial>
        <origin xyz="0.10606534334643407 -2.5754487934477176e-05 0.218101514724435" rpy="0 0 0"/>
        <mass value="16.262774451109365"/>
        <inertia ixx="0.316746" iyy="0.297036" izz="0.148674" ixy="-2e-05" iyz="-0.010615" ixz="0.035712"/>
      </inertial>
      <visual>
        <origin xyz="0.082038 -0.000502 -0.303534" rpy="0 0 0"/>
        <geometry>
          <!-- <mesh filename="package://stand_chest_description/meshes/chest_1.stl" scale="0.001 0.001 0.001"/> -->
          <mesh filename="package://gopher_description/stand_chest_description/meshes/chest.stl"/>
        </geometry>
        <material name="silver"/>
      </visual>
      <collision>
        <origin xyz="0.082038 -0.000502 -0.303534" rpy="0 0 0"/>
        <geometry>
          <!-- <mesh filename="package://stand_chest_description/meshes/chest_1.stl" scale="0.001 0.001 0.001"/> -->
          <mesh filename="package://gopher_description/stand_chest_description/meshes/chest.stl"/>
        </geometry>
      </collision>
    </link>

    <link name="${prefix}right_mounting_plate">
      <inertial>
        <origin xyz="4.7281095104378945e-07 -0.0567010174331518 -0.049390420271976265" rpy="0 0 0"/>
        <mass value="0.39829293027064405"/>
        <inertia ixx="0.000743" iyy="0.000706" izz="0.000705" ixy="0.0" iyz="-0.000368" ixz="0.0"/>
      </inertial>
      <visual>
        <origin xyz="-0.079962 0.081418 -0.57074" rpy="0 0 0"/>
        <geometry>
          <mesh filename="package://gopher_description/stand_chest_description/meshes/right_kinova_mounting_plate.stl"/>
        </geometry>
        <material name="silver"/>
      </visual>
      <collision>
        <origin xyz="-0.079962 0.081418 -0.57074" rpy="0 0 0"/>
        <geometry>
          <mesh filename="package://gopher_description/stand_chest_description/meshes/right_kinova_mounting_plate.stl"/>
        </geometry>
      </collision>
    </link>

    <link name="${prefix}left_mounting_plate">
      <inertial>
        <origin xyz="4.728109729568164e-07 0.056701389156455395 -0.04939042027199214" rpy="0 0 0"/>
        <mass value="0.39829293027064805"/>
        <inertia ixx="0.000743" iyy="0.000706" izz="0.000705" ixy="0.0" iyz="0.000368" ixz="-0.0"/>
      </inertial>
      <visual>
        <origin xyz="-0.079962 -0.082422 -0.57074" rpy="0 0 0"/>
        <geometry>
          <mesh filename="package://gopher_description/stand_chest_description/meshes/left_kinova_mounting_plate.stl"/>
        </geometry>
        <material name="silver"/>
      </visual>
      <collision>
        <origin xyz="-0.079962 -0.082422 -0.57074" rpy="0 0 0"/>
        <geometry>
          <mesh filename="package://gopher_description/stand_chest_description/meshes/left_kinova_mounting_plate.stl"/>
        </geometry>
      </collision>
    </link>

    <!-- Copying over the camera links and joints from torso_description -->
    
    <link name="${prefix}main_cam_support">
      <collision>
        <origin rpy="0 0 0" xyz="0 0 0.01"/>
        <geometry>
          <box size="0.08 0.08 0.02"/>
        </geometry>
      </collision>
      <visual>
        <origin rpy="0 0 0" xyz="0 0 0.01"/>
        <geometry>
          <box size="0.08 0.08 0.02"/>
        </geometry>
        <material name="">
          <color rgba="0.5 0.6 0.7 1"/>
        </material>
      </visual>
      <inertial>
        <origin rpy="0 0 0" xyz="0 0 0.01"/>
        <mass value="0.36"/>
        <inertia ixx="2.04e-04" ixy="0.0" ixz="0.0" iyy="2.04e-04" iyz="0.0" izz="3.84e-04"/>
      </inertial>
    </link>

    <joint name="${prefix}main_cam_support_joint" type="fixed">
      <parent link="${prefix}chest"/>
      <child link="${prefix}main_cam_support"/>
      <origin rpy="0 0 0" xyz="0.0 0.0 0.8"/>
      <axis xyz="0 0 1"/>
    </joint>

    <link name="${prefix}main_cam_yaw_link">
      <collision>
        <origin rpy="0 0 0" xyz="0 0 0.03"/>
        <geometry>
          <box size="0.03 0.03 0.06"/>
        </geometry>
      </collision>
      <visual>
        <origin rpy="0 0 0" xyz="0 0 0.03"/>
        <geometry>
          <box size="0.03 0.03 0.06"/>
        </geometry>
        <material name="blue">
          <color rgba="0 0 1 1"/>
        </material>
      </visual>
      <inertial>
        <origin rpy="0 0 0" xyz="0 0 0.03"/>
        <mass value="0.36"/>
        <inertia ixx="1.35e-01" ixy="0.0" ixz="0.0" iyy="1.35e-01" iyz="0.0" izz="5.4e-02"/>
      </inertial>
    </link>

    <joint name="${prefix}main_cam_yaw_joint" type="revolute">
      <parent link="${prefix}main_cam_support"/>
      <child link="${prefix}main_cam_yaw_link"/>
      <origin rpy="0 0 0" xyz="0 0 0.02"/>
      <axis xyz="0 0 1"/>
      <limit effort="20" lower="-1.047" upper="1.047" velocity="1.0"/>
    </joint>

    <link name="${prefix}main_cam_pitch_link">
      <collision>
        <origin rpy="0 1.5708 0" xyz="0.03 0 0"/>
        <geometry>
          <box size="0.03 0.03 0.06"/>
        </geometry>
      </collision>
      <visual>
        <origin rpy="0 1.5708 0" xyz="0.03 0 0"/>
        <geometry>
          <box size="0.03 0.03 0.06"/>
        </geometry>
        <material name="red">
          <color rgba="1 0 0 1"/>
        </material>
      </visual>
      <inertial>
        <origin rpy="0 1.5708 0" xyz="0.03 0 0"/>
        <mass value="0.36"/>
        <inertia ixx="1.35e-01" ixy="0.0" ixz="0.0" iyy="1.35e-01" iyz="0.0" izz="5.4e-02"/>
      </inertial>
    </link>

    <joint name="${prefix}main_cam_pitch_joint" type="revolute">
      <parent link="${prefix}main_cam_yaw_link"/>
      <child link="${prefix}main_cam_pitch_link"/>
      <origin rpy="1.5708 0 0" xyz="0.0 0.0 0.06"/>
      <axis xyz="0 0 1"/>
      <limit effort="20" lower="-1.047" upper="1.047" velocity="1.0"/>
    </joint>


  </xacro:macro>

</robot>
