<?xml version="1.0" encoding="utf-8"?>
<!-- =================================================================================== -->
<!-- |    This document was autogenerated by xacro from gopher_presence.xacro                   | -->
<!-- |    EDITING THIS FILE BY HAND IS NOT RECOMMENDED                                 | -->
<!-- =================================================================================== -->
<robot name="Gopher Presence">
  <link name="gopher_presence/base_link"/>
  <link name="gopher_presence/chassis_link">
    <inertial>
      <origin rpy="0 0 0" xyz="-0.0036 0.0 0.0014"/>
      <mass value="70.1294"/>
      <inertia ixx="1.225" ixy="0.0099" ixz="0.0062" iyy="1.2853" iyz="-0.0034" izz="0.987"/>
    </inertial>
    <visual>
      <origin rpy="0 0 0" xyz="0 0 0"/>
      <geometry>
        <mesh filename="package://gopher_description/fetch_description/meshes/base_link.dae"/>
      </geometry>
    </visual>
    <collision>
      <origin rpy="0 0 0" xyz="0 0 0"/>
      <geometry>
        <mesh filename="package://gopher_description/fetch_description/meshes/base_link_collision.STL"/>
      </geometry>
    </collision>
  </link>
  <joint name="gopher_presence/base_joint" type="fixed">
    <parent link="gopher_presence/base_link"/>
    <child link="gopher_presence/chassis_link"/>
  </joint>
  <link name="gopher_presence/r_wheel_link">
    <inertial>
      <origin rpy="0 0 0" xyz="0 0 0"/>
      <mass value="4.3542"/>
      <inertia ixx="0.0045" ixy="0" ixz="0" iyy="0.005" iyz="0" izz="0.0045"/>
    </inertial>
    <visual>
      <origin rpy="0 0 0" xyz="0 0 0"/>
      <geometry>
        <mesh filename="package://gopher_description/fetch_description/meshes/r_wheel_link.STL"/>
      </geometry>
      <material name="">
        <color rgba="0.086 0.506 0.767 1"/>
      </material>
    </visual>
    <collision>
      <origin rpy="0 0 0" xyz="0 0 0"/>
      <geometry>
        <mesh filename="package://gopher_description/fetch_description/meshes/r_wheel_link_collision.STL"/>
      </geometry>
    </collision>
  </link>
  <joint name="gopher_presence/r_wheel_joint" type="continuous">
    <origin rpy="-6.123E-17 0 0" xyz="0.0012914 -0.18738 0.0605"/>
    <parent link="gopher_presence/chassis_link"/>
    <child link="gopher_presence/r_wheel_link"/>
    <axis xyz="0 1 0"/>
    <limit effort="8.85" velocity="34.8"/>
  </joint>
  <link name="gopher_presence/l_wheel_link">
    <inertial>
      <origin rpy="0 0 0" xyz="0 0 0"/>
      <mass value="4.3542"/>
      <inertia ixx="0.0045" ixy="0" ixz="0" iyy="0.005" iyz="0" izz="0.0045"/>
    </inertial>
    <visual>
      <origin rpy="0 0 0" xyz="0 0 0"/>
      <geometry>
        <mesh filename="package://gopher_description/fetch_description/meshes/l_wheel_link.STL"/>
      </geometry>
      <material name="">
        <color rgba="0.086 0.506 0.767 1"/>
      </material>
    </visual>
    <collision>
      <origin rpy="0 0 0" xyz="0 0 0"/>
      <geometry>
        <mesh filename="package://gopher_description/fetch_description/meshes/l_wheel_link_collision.STL"/>
      </geometry>
    </collision>
  </link>
  <joint name="gopher_presence/l_wheel_joint" type="continuous">
    <origin rpy="-6.123E-17 0 0" xyz="0.0012914 0.18738 0.0605"/>
    <parent link="gopher_presence/chassis_link"/>
    <child link="gopher_presence/l_wheel_link"/>
    <axis xyz="0 1 0"/>
    <limit effort="8.85" velocity="34.8"/>
  </joint>
  <link name="gopher_presence/estop_link">
    <inertial>
      <origin rpy="0 0 0" xyz="0.002434512737072 -0.00330608315239905 0.00665139196650039"/>
      <mass value="0.00196130439134723"/>
      <inertia ixx="3.02810026604417E-07" ixy="-1.5862023118056E-08" ixz="3.16561396557437E-08" iyy="2.93322917127605E-07" iyz="-4.28833522751273E-08" izz="2.28513272627183E-07"/>
    </inertial>
    <visual>
      <origin rpy="0 0 0" xyz="0 0 0"/>
      <geometry>
        <mesh filename="package://gopher_description/fetch_description/meshes/estop_link.STL"/>
      </geometry>
      <material name="">
        <color rgba="0.8 0 0 1"/>
      </material>
    </visual>
    <collision>
      <origin rpy="0 0 0" xyz="0 0 0"/>
      <geometry>
        <mesh filename="package://gopher_description/fetch_description/meshes/estop_link_collision.STL"/>
      </geometry>
    </collision>
  </link>
  <joint name="gopher_presence/estop_joint" type="fixed">
    <origin rpy="1.5708 0 0" xyz="-0.12465 0.23892 0.31127"/>
    <parent link="gopher_presence/chassis_link"/>
    <child link="gopher_presence/estop_link"/>
    <axis xyz="0 0 0"/>
  </joint>
  <link name="gopher_presence/laser_link">
    <inertial>
      <origin rpy="0 0 0" xyz="-0.0306228970175641 0.0007091682908278 0.0551974119471302"/>
      <mass value="0.00833634573995571"/>
      <inertia ixx="1.01866461240801E-06" ixy="-5.88447626567756E-08" ixz="7.83857244757914E-08" iyy="5.10039589974707E-07" iyz="-7.12664289617235E-09" izz="1.28270671527309E-06"/>
    </inertial>
    <visual>
      <origin rpy="0 0 0" xyz="0 0 0"/>
      <geometry>
        <mesh filename="package://gopher_description/fetch_description/meshes/laser_link.STL"/>
      </geometry>
      <material name="">
        <color rgba="0.792156862745098 0.819607843137255 0.933333333333333 1"/>
      </material>
    </visual>
    <collision>
      <origin rpy="0 0 0" xyz="0 0 0"/>
      <geometry>
        <mesh filename="package://gopher_description/fetch_description/meshes/laser_link_collision.STL"/>
      </geometry>
    </collision>
  </link>
  <joint name="gopher_presence/laser_joint" type="fixed">
    <origin rpy="3.14159265359 0 0" xyz="0.235 0 0.2878"/>
    <parent link="gopher_presence/chassis_link"/>
    <child link="gopher_presence/laser_link"/>
    <axis xyz="0 0 0"/>
  </joint>
  <link name="gopher_presence/base_camera_link">
    <inertial>
      <origin rpy="0 0 0" xyz="0 0 0"/>
      <mass value="0.001"/>
      <inertia ixx="1E-5" ixy="0" ixz="0" iyy="1E-5" iyz="-0" izz="1E-5"/>
    </inertial>
  </link>
  <joint name="gopher_presence/base_camera_joint" type="fixed">
    <origin rpy="0 -0.17453292519943 0" xyz="0.2645 0 0.198"/>
    <parent link="gopher_presence/chassis_link"/>
    <child link="gopher_presence/base_camera_link"/>
  </joint>
  <link name="gopher_presence/base_camera_optical_frame">
    <inertial>
      <origin rpy="0 0 0" xyz="0 0 0"/>
      <mass value="0.001"/>
      <inertia ixx="1E-5" ixy="0" ixz="0" iyy="1E-5" iyz="-0" izz="1E-5"/>
    </inertial>
  </link>
  <joint name="gopher_presence/base_camera_optical_joint" type="fixed">
    <origin rpy="1.5707963267966 0 1.5707963267966" xyz="0 0 0"/>
    <parent link="gopher_presence/base_camera_link"/>
    <child link="gopher_presence/base_camera_optical_frame"/>
  </joint>
  <link name="gopher_presence/torso">
    <inertial>
      <origin rpy="0 0 0" xyz="0.0 0.0 0.4"/>
      <mass value="12.0"/>
      <inertia ixx="0.68" ixy="0.0" ixz="0.0" iyy="0.73" iyz="0.0" izz="0.13"/>
    </inertial>
    <visual>
      <origin rpy="0 0 0" xyz="0 0 0"/>
      <geometry>
        <mesh filename="package://gopher_description/torso_description/meshes/torso.dae"/>
      </geometry>
      <material name="">
        <color rgba="0.3 0.3 0.3 1"/>
      </material>
    </visual>
    <collision>
      <origin rpy="0 0 0" xyz="0 0 0"/>
      <geometry>
        <mesh filename="package://gopher_description/torso_description/meshes/torso.dae"/>
      </geometry>
    </collision>
  </link>
  <joint name="gopher_presence/torso_joint" type="fixed">
    <parent link="gopher_presence/chassis_link"/>
    <child link="gopher_presence/torso"/>
    <origin rpy="0 0 0" xyz="-0.0 0 0.36"/>
    <axis xyz="0 0 1"/>
  </joint>
  <link name="gopher_presence/main_cam_support">
    <collision>
      <origin rpy="0 0 0" xyz="0 0 0.01"/>
      <geometry>
        <box size="0.08 0.08 0.02"/>
      </geometry>
    </collision>
    <visual>
      <origin rpy="0 0 0" xyz="0 0 0.01"/>
      <geometry>
        <box size="0.08 0.08 0.02"/>
      </geometry>
      <material name="">
        <color rgba="0.5 0.6 0.7 1"/>
      </material>
    </visual>
    <inertial>
      <origin rpy="0 0 0" xyz="0 0 0.01"/>
      <mass value="0.36"/>
      <inertia ixx="2.04e-04" ixy="0.0" ixz="0.0" iyy="2.04e-04" iyz="0.0" izz="3.84e-04"/>
    </inertial>
  </link>
  <joint name="gopher_presence/main_cam_support_joint" type="fixed">
    <parent link="gopher_presence/torso"/>
    <child link="gopher_presence/main_cam_support"/>
    <origin rpy="0 0 0" xyz="0.0 0.0 0.8"/>
    <axis xyz="0 0 1"/>
  </joint>
  <link name="gopher_presence/main_cam_yaw_link">
    <collision>
      <origin rpy="0 0 0" xyz="0 0 0.03"/>
      <geometry>
        <box size="0.03 0.03 0.06"/>
      </geometry>
    </collision>
    <visual>
      <origin rpy="0 0 0" xyz="0 0 0.03"/>
      <geometry>
        <box size="0.03 0.03 0.06"/>
      </geometry>
      <material name="blue">
        <color rgba="0 0 1 1"/>
      </material>
    </visual>
    <inertial>
      <origin rpy="0 0 0" xyz="0 0 0.03"/>
      <mass value="0.36"/>
      <inertia ixx="1.35e-01" ixy="0.0" ixz="0.0" iyy="1.35e-01" iyz="0.0" izz="5.4e-02"/>
    </inertial>
  </link>
  <joint name="gopher_presence/main_cam_yaw_joint" type="revolute">
    <parent link="gopher_presence/main_cam_support"/>
    <child link="gopher_presence/main_cam_yaw_link"/>
    <origin rpy="0 0 0" xyz="0 0 0.02"/>
    <axis xyz="0 0 1"/>
    <limit effort="20" lower="-1.047" upper="1.047" velocity="1.0"/>
  </joint>
  <link name="gopher_presence/main_cam_pitch_link">
    <collision>
      <origin rpy="0 1.5708 0" xyz="0.03 0 0"/>
      <geometry>
        <box size="0.03 0.03 0.06"/>
      </geometry>
    </collision>
    <visual>
      <origin rpy="0 1.5708 0" xyz="0.03 0 0"/>
      <geometry>
        <box size="0.03 0.03 0.06"/>
      </geometry>
      <material name="red">
        <color rgba="1 0 0 1"/>
      </material>
    </visual>
    <inertial>
      <origin rpy="0 1.5708 0" xyz="0.03 0 0"/>
      <mass value="0.36"/>
      <inertia ixx="1.35e-01" ixy="0.0" ixz="0.0" iyy="1.35e-01" iyz="0.0" izz="5.4e-02"/>
    </inertial>
  </link>
  <joint name="gopher_presence/main_cam_pitch_joint" type="revolute">
    <parent link="gopher_presence/main_cam_yaw_link"/>
    <child link="gopher_presence/main_cam_pitch_link"/>
    <origin rpy="1.5708 0 0" xyz="0.0 0.0 0.06"/>
    <axis xyz="0 0 1"/>
    <limit effort="20" lower="-1.047" upper="1.047" velocity="1.0"/>
  </joint>
  <material name="aluminum">
    <color rgba="0.5 0.5 0.5 1"/>
  </material>
  <!-- camera body, with origin at bottom screw mount -->
  <joint name="gopher_presence/main_cam_joint" type="fixed">
    <origin rpy="-1.57 0 0" xyz="0.06 -0.01 0.0"/>
    <parent link="gopher_presence/main_cam_pitch_link"/>
    <child link="gopher_presence/main_cam_bottom_screw_frame"/>
  </joint>
  <link name="gopher_presence/main_cam_bottom_screw_frame">
    <inertial>
      <origin rpy="0 0 0" xyz="0 0 0"/>
      <mass value="0.001"/>
      <inertia ixx="1E-5" ixy="0" ixz="0" iyy="1E-5" iyz="-0" izz="1E-5"/>
    </inertial>
  </link>
  <joint name="gopher_presence/main_cam_link_joint" type="fixed">
    <origin rpy="0 0 0" xyz="0 0.0175 0.0125"/>
    <parent link="gopher_presence/main_cam_bottom_screw_frame"/>
    <child link="gopher_presence/main_cam_link"/>
  </joint>
  <link name="gopher_presence/main_cam_link">
    <visual>
      <origin rpy="1.57079632679 0 1.57079632679" xyz="0.0149 -0.0175 0"/>
      <geometry>
        <mesh filename="package://gopher_description/realsense2_description/meshes/d435.dae"/>
      </geometry>
      <material name="aluminum"/>
    </visual>
    <collision>
      <origin rpy="0 0 0" xyz="0 -0.0175 0"/>
      <geometry>
        <box size="0.02505 0.09 0.025"/>
      </geometry>
    </collision>
    <inertial>
      <!-- The following are not reliable values, and should not be used for modeling -->
      <mass value="0.564"/>
      <origin xyz="0 0 0"/>
      <inertia ixx="0.003881243" ixy="0.0" ixz="0.0" iyy="0.000498940" iyz="0.0" izz="0.003879257"/>
    </inertial>
  </link>
  <!-- camera depth joints and links -->
  <joint name="gopher_presence/main_cam_depth_joint" type="fixed">
    <origin rpy="0 0 0" xyz="0 0 0"/>
    <parent link="gopher_presence/main_cam_link"/>
    <child link="gopher_presence/main_cam_depth_frame"/>
  </joint>
  <link name="gopher_presence/main_cam_depth_frame">
    <inertial>
      <origin rpy="0 0 0" xyz="0 0 0"/>
      <mass value="0.001"/>
      <inertia ixx="1E-5" ixy="0" ixz="0" iyy="1E-5" iyz="-0" izz="1E-5"/>
    </inertial>
  </link>
  <!-- camera color joints and links -->
  <joint name="gopher_presence/main_cam_color_joint" type="fixed">
    <origin rpy="0 0 0" xyz="0 0.015 0"/>
    <parent link="gopher_presence/main_cam_depth_frame"/>
    <child link="gopher_presence/main_cam_color_frame"/>
  </joint>
  <link name="gopher_presence/main_cam_color_frame">
    <inertial>
      <origin rpy="0 0 0" xyz="0 0 0"/>
      <mass value="0.001"/>
      <inertia ixx="1E-5" ixy="0" ixz="0" iyy="1E-5" iyz="-0" izz="1E-5"/>
    </inertial>
  </link>
</robot>
