<?xml version="1.0" encoding="utf-8"?>
<!-- =================================================================================== -->
<!-- |    This document was autogenerated by xacro from gopher.xacro                   | -->
<!-- |    EDITING THIS FILE BY HAND IS NOT RECOMMENDED                                 | -->
<!-- =================================================================================== -->
<robot name="Gopher">
  <link name="gopher/base_link"/>
  <link name="gopher/chassis_link">
    <inertial>
      <origin rpy="0 0 0" xyz="-0.0036 0.0 0.0014"/>
      <mass value="70.1294"/>
      <inertia ixx="1.225" ixy="0.0099" ixz="0.0062" iyy="1.2853" iyz="-0.0034" izz="0.987"/>
    </inertial>
    <visual>
      <origin rpy="0 0 0" xyz="0 0 0"/>
      <geometry>
        <mesh filename="package://gopher_description/fetch_description/meshes/base_link.dae"/>
      </geometry>
    </visual>
    <collision>
      <origin rpy="0 0 0" xyz="0 0 0"/>
      <geometry>
        <mesh filename="package://gopher_description/fetch_description/meshes/base_link_collision.STL"/>
      </geometry>
    </collision>
  </link>
  <joint name="gopher/base_joint" type="fixed">
    <parent link="gopher/base_link"/>
    <child link="gopher/chassis_link"/>
  </joint>
  <link name="gopher/r_wheel_link">
    <inertial>
      <origin rpy="0 0 0" xyz="0 0 0"/>
      <mass value="4.3542"/>
      <inertia ixx="0.0045" ixy="0" ixz="0" iyy="0.005" iyz="0" izz="0.0045"/>
    </inertial>
    <visual>
      <origin rpy="0 0 0" xyz="0 0 0"/>
      <geometry>
        <mesh filename="package://gopher_description/fetch_description/meshes/r_wheel_link.STL"/>
      </geometry>
      <material name="">
        <color rgba="0.086 0.506 0.767 1"/>
      </material>
    </visual>
    <collision>
      <origin rpy="0 0 0" xyz="0 0 0"/>
      <geometry>
        <mesh filename="package://gopher_description/fetch_description/meshes/r_wheel_link_collision.STL"/>
      </geometry>
    </collision>
  </link>
  <joint name="gopher/r_wheel_joint" type="continuous">
    <origin rpy="-6.123E-17 0 0" xyz="0.0012914 -0.18738 0.0605"/>
    <parent link="gopher/chassis_link"/>
    <child link="gopher/r_wheel_link"/>
    <axis xyz="0 1 0"/>
    <limit effort="8.85" velocity="34.8"/>
  </joint>
  <link name="gopher/l_wheel_link">
    <inertial>
      <origin rpy="0 0 0" xyz="0 0 0"/>
      <mass value="4.3542"/>
      <inertia ixx="0.0045" ixy="0" ixz="0" iyy="0.005" iyz="0" izz="0.0045"/>
    </inertial>
    <visual>
      <origin rpy="0 0 0" xyz="0 0 0"/>
      <geometry>
        <mesh filename="package://gopher_description/fetch_description/meshes/l_wheel_link.STL"/>
      </geometry>
      <material name="">
        <color rgba="0.086 0.506 0.767 1"/>
      </material>
    </visual>
    <collision>
      <origin rpy="0 0 0" xyz="0 0 0"/>
      <geometry>
        <mesh filename="package://gopher_description/fetch_description/meshes/l_wheel_link_collision.STL"/>
      </geometry>
    </collision>
  </link>
  <joint name="gopher/l_wheel_joint" type="continuous">
    <origin rpy="-6.123E-17 0 0" xyz="0.0012914 0.18738 0.0605"/>
    <parent link="gopher/chassis_link"/>
    <child link="gopher/l_wheel_link"/>
    <axis xyz="0 1 0"/>
    <limit effort="8.85" velocity="34.8"/>
  </joint>
  <link name="gopher/estop_link">
    <inertial>
      <origin rpy="0 0 0" xyz="0.002434512737072 -0.00330608315239905 0.00665139196650039"/>
      <mass value="0.00196130439134723"/>
      <inertia ixx="3.02810026604417E-07" ixy="-1.5862023118056E-08" ixz="3.16561396557437E-08" iyy="2.93322917127605E-07" iyz="-4.28833522751273E-08" izz="2.28513272627183E-07"/>
    </inertial>
    <visual>
      <origin rpy="0 0 0" xyz="0 0 0"/>
      <geometry>
        <mesh filename="package://gopher_description/fetch_description/meshes/estop_link.STL"/>
      </geometry>
      <material name="">
        <color rgba="0.8 0 0 1"/>
      </material>
    </visual>
    <collision>
      <origin rpy="0 0 0" xyz="0 0 0"/>
      <geometry>
        <mesh filename="package://gopher_description/fetch_description/meshes/estop_link_collision.STL"/>
      </geometry>
    </collision>
  </link>
  <joint name="gopher/estop_joint" type="fixed">
    <origin rpy="1.5708 0 0" xyz="-0.12465 0.23892 0.31127"/>
    <parent link="gopher/chassis_link"/>
    <child link="gopher/estop_link"/>
    <axis xyz="0 0 0"/>
  </joint>
  <link name="gopher/laser_link">
    <inertial>
      <origin rpy="0 0 0" xyz="-0.0306228970175641 0.0007091682908278 0.0551974119471302"/>
      <mass value="0.00833634573995571"/>
      <inertia ixx="1.01866461240801E-06" ixy="-5.88447626567756E-08" ixz="7.83857244757914E-08" iyy="5.10039589974707E-07" iyz="-7.12664289617235E-09" izz="1.28270671527309E-06"/>
    </inertial>
    <visual>
      <origin rpy="0 0 0" xyz="0 0 0"/>
      <geometry>
        <mesh filename="package://gopher_description/fetch_description/meshes/laser_link.STL"/>
      </geometry>
      <material name="">
        <color rgba="0.792156862745098 0.819607843137255 0.933333333333333 1"/>
      </material>
    </visual>
    <collision>
      <origin rpy="0 0 0" xyz="0 0 0"/>
      <geometry>
        <mesh filename="package://gopher_description/fetch_description/meshes/laser_link_collision.STL"/>
      </geometry>
    </collision>
  </link>
  <joint name="gopher/laser_joint" type="fixed">
    <origin rpy="3.14159265359 0 0" xyz="0.235 0 0.2878"/>
    <parent link="gopher/chassis_link"/>
    <child link="gopher/laser_link"/>
    <axis xyz="0 0 0"/>
  </joint>
  <link name="gopher/base_camera_link">
    <inertial>
      <origin rpy="0 0 0" xyz="0 0 0"/>
      <mass value="0.001"/>
      <inertia ixx="1E-5" ixy="0" ixz="0" iyy="1E-5" iyz="-0" izz="1E-5"/>
    </inertial>
  </link>
  <joint name="gopher/base_camera_joint" type="fixed">
    <origin rpy="0 -0.17453292519943 0" xyz="0.2645 0 0.198"/>
    <parent link="gopher/chassis_link"/>
    <child link="gopher/base_camera_link"/>
  </joint>
  <link name="gopher/base_camera_optical_frame">
    <inertial>
      <origin rpy="0 0 0" xyz="0 0 0"/>
      <mass value="0.001"/>
      <inertia ixx="1E-5" ixy="0" ixz="0" iyy="1E-5" iyz="-0" izz="1E-5"/>
    </inertial>
  </link>
  <joint name="gopher/base_camera_optical_joint" type="fixed">
    <origin rpy="1.5707963267966 0 1.5707963267966" xyz="0 0 0"/>
    <parent link="gopher/base_camera_link"/>
    <child link="gopher/base_camera_optical_frame"/>
  </joint>
  <link name="gopher/torso">
    <inertial>
      <origin rpy="0 0 0" xyz="0.0 0.0 0.4"/>
      <mass value="12.0"/>
      <inertia ixx="0.68" ixy="0.0" ixz="0.0" iyy="0.73" iyz="0.0" izz="0.13"/>
    </inertial>
    <visual>
      <origin rpy="0 0 0" xyz="0 0 0"/>
      <geometry>
        <mesh filename="package://gopher_description/torso_description/meshes/torso.dae"/>
      </geometry>
      <material name="">
        <color rgba="0.3 0.3 0.3 1"/>
      </material>
    </visual>
    <collision>
      <origin rpy="0 0 0" xyz="0 0 0"/>
      <geometry>
        <mesh filename="package://gopher_description/torso_description/meshes/torso.dae"/>
      </geometry>
    </collision>
  </link>
  <joint name="gopher/torso_joint" type="fixed">
    <parent link="gopher/chassis_link"/>
    <child link="gopher/torso"/>
    <origin rpy="0 0 0" xyz="-0.0 0 0.36"/>
    <axis xyz="0 0 1"/>
  </joint>
  <link name="gopher/main_cam_support">
    <collision>
      <origin rpy="0 0 0" xyz="0 0 0.01"/>
      <geometry>
        <box size="0.08 0.08 0.02"/>
      </geometry>
    </collision>
    <visual>
      <origin rpy="0 0 0" xyz="0 0 0.01"/>
      <geometry>
        <box size="0.08 0.08 0.02"/>
      </geometry>
      <material name="">
        <color rgba="0.5 0.6 0.7 1"/>
      </material>
    </visual>
    <inertial>
      <origin rpy="0 0 0" xyz="0 0 0.01"/>
      <mass value="0.36"/>
      <inertia ixx="2.04e-04" ixy="0.0" ixz="0.0" iyy="2.04e-04" iyz="0.0" izz="3.84e-04"/>
    </inertial>
  </link>
  <joint name="gopher/main_cam_support_joint" type="fixed">
    <parent link="gopher/torso"/>
    <child link="gopher/main_cam_support"/>
    <origin rpy="0 0 0" xyz="0.0 0.0 0.8"/>
    <axis xyz="0 0 1"/>
  </joint>
  <link name="gopher/main_cam_yaw_link">
    <collision>
      <origin rpy="0 0 0" xyz="0 0 0.03"/>
      <geometry>
        <box size="0.03 0.03 0.06"/>
      </geometry>
    </collision>
    <visual>
      <origin rpy="0 0 0" xyz="0 0 0.03"/>
      <geometry>
        <box size="0.03 0.03 0.06"/>
      </geometry>
      <material name="blue">
        <color rgba="0 0 1 1"/>
      </material>
    </visual>
    <inertial>
      <origin rpy="0 0 0" xyz="0 0 0.03"/>
      <mass value="0.36"/>
      <inertia ixx="1.35e-01" ixy="0.0" ixz="0.0" iyy="1.35e-01" iyz="0.0" izz="5.4e-02"/>
    </inertial>
  </link>
  <joint name="gopher/main_cam_yaw_joint" type="revolute">
    <parent link="gopher/main_cam_support"/>
    <child link="gopher/main_cam_yaw_link"/>
    <origin rpy="0 0 0" xyz="0 0 0.02"/>
    <axis xyz="0 0 1"/>
    <limit effort="20" lower="-1.047" upper="1.047" velocity="1.0"/>
  </joint>
  <link name="gopher/main_cam_pitch_link">
    <collision>
      <origin rpy="0 1.5708 0" xyz="0.03 0 0"/>
      <geometry>
        <box size="0.03 0.03 0.06"/>
      </geometry>
    </collision>
    <visual>
      <origin rpy="0 1.5708 0" xyz="0.03 0 0"/>
      <geometry>
        <box size="0.03 0.03 0.06"/>
      </geometry>
      <material name="red">
        <color rgba="1 0 0 1"/>
      </material>
    </visual>
    <inertial>
      <origin rpy="0 1.5708 0" xyz="0.03 0 0"/>
      <mass value="0.36"/>
      <inertia ixx="1.35e-01" ixy="0.0" ixz="0.0" iyy="1.35e-01" iyz="0.0" izz="5.4e-02"/>
    </inertial>
  </link>
  <joint name="gopher/main_cam_pitch_joint" type="revolute">
    <parent link="gopher/main_cam_yaw_link"/>
    <child link="gopher/main_cam_pitch_link"/>
    <origin rpy="1.5708 0 0" xyz="0.0 0.0 0.06"/>
    <axis xyz="0 0 1"/>
    <limit effort="20" lower="-1.047" upper="1.047" velocity="1.0"/>
  </joint>
  <material name="aluminum">
    <color rgba="0.5 0.5 0.5 1"/>
  </material>
  <!-- camera body, with origin at bottom screw mount -->
  <joint name="gopher/main_cam_joint" type="fixed">
    <origin rpy="-1.57 0 0" xyz="0.06 -0.01 0.0"/>
    <parent link="gopher/main_cam_pitch_link"/>
    <child link="gopher/main_cam_bottom_screw_frame"/>
  </joint>
  <link name="gopher/main_cam_bottom_screw_frame">
    <inertial>
      <origin rpy="0 0 0" xyz="0 0 0"/>
      <mass value="0.001"/>
      <inertia ixx="1E-5" ixy="0" ixz="0" iyy="1E-5" iyz="-0" izz="1E-5"/>
    </inertial>
  </link>
  <joint name="gopher/main_cam_link_joint" type="fixed">
    <origin rpy="0 0 0" xyz="0 0.0175 0.0125"/>
    <parent link="gopher/main_cam_bottom_screw_frame"/>
    <child link="gopher/main_cam_link"/>
  </joint>
  <link name="gopher/main_cam_link">
    <visual>
      <origin rpy="1.57079632679 0 1.57079632679" xyz="0.0149 -0.0175 0"/>
      <geometry>
        <mesh filename="package://gopher_description/realsense2_description/meshes/d435.dae"/>
      </geometry>
      <material name="aluminum"/>
    </visual>
    <collision>
      <origin rpy="0 0 0" xyz="0 -0.0175 0"/>
      <geometry>
        <box size="0.02505 0.09 0.025"/>
      </geometry>
    </collision>
    <inertial>
      <!-- The following are not reliable values, and should not be used for modeling -->
      <mass value="0.564"/>
      <origin xyz="0 0 0"/>
      <inertia ixx="0.003881243" ixy="0.0" ixz="0.0" iyy="0.000498940" iyz="0.0" izz="0.003879257"/>
    </inertial>
  </link>
  <!-- camera depth joints and links -->
  <joint name="gopher/main_cam_depth_joint" type="fixed">
    <origin rpy="0 0 0" xyz="0 0 0"/>
    <parent link="gopher/main_cam_link"/>
    <child link="gopher/main_cam_depth_frame"/>
  </joint>
  <link name="gopher/main_cam_depth_frame">
    <inertial>
      <origin rpy="0 0 0" xyz="0 0 0"/>
      <mass value="0.001"/>
      <inertia ixx="1E-5" ixy="0" ixz="0" iyy="1E-5" iyz="-0" izz="1E-5"/>
    </inertial>
  </link>
  <!-- camera color joints and links -->
  <joint name="gopher/main_cam_color_joint" type="fixed">
    <origin rpy="0 0 0" xyz="0 0.015 0"/>
    <parent link="gopher/main_cam_depth_frame"/>
    <child link="gopher/main_cam_color_frame"/>
  </joint>
  <link name="gopher/main_cam_color_frame">
    <inertial>
      <origin rpy="0 0 0" xyz="0 0 0"/>
      <mass value="0.001"/>
      <inertia ixx="1E-5" ixy="0" ixz="0" iyy="1E-5" iyz="-0" izz="1E-5"/>
    </inertial>
  </link>
  <!-- Run the macros -->
  <!-- Attach to parent link -->
  <joint name="gopher/right_arm_shoulder_to_arm_root" type="fixed">
    <child link="gopher/right_arm_base_link"/>
    <parent link="gopher/torso"/>
    <origin rpy="1.5708 0 0" xyz="-0.03 -0.03 0.7"/>
  </joint>
  <link name="gopher/right_arm_base_link">
    <inertial>
      <origin rpy="0 0 0" xyz="-0.000648 -0.000166 0.084487"/>
      <mass value="1.697"/>
      <inertia ixx="0.004622" ixy="9E-06" ixz="6E-05" iyy="0.004495" iyz="9E-06" izz="0.002079"/>
    </inertial>
    <visual>
      <origin rpy="0 0 0" xyz="0 0 0"/>
      <geometry>
        <mesh filename="package://kortex_description/arms/gen3/7dof/meshes/base_link.STL"/>
      </geometry>
      <material name="">
        <color rgba="0.75294 0.75294 0.75294 1"/>
      </material>
    </visual>
    <collision>
      <origin rpy="0 0 0" xyz="0 0 0"/>
      <geometry>
        <mesh filename="package://kortex_description/arms/gen3/7dof/meshes/base_link.STL"/>
      </geometry>
    </collision>
  </link>
  <link name="gopher/right_arm_shoulder_link">
    <inertial>
      <origin rpy="0 0 0" xyz="-2.3E-05 -0.010364 -0.07336"/>
      <mass value="1.3773"/>
      <inertia ixx="0.00457" ixy="1E-06" ixz="2E-06" iyy="0.004831" iyz="0.000448" izz="0.001409"/>
    </inertial>
    <visual>
      <origin rpy="0 0 0" xyz="0 0 0"/>
      <geometry>
        <mesh filename="package://kortex_description/arms/gen3/7dof/meshes/shoulder_link.STL"/>
      </geometry>
      <material name="">
        <color rgba="0.75294 0.75294 0.75294 1"/>
      </material>
    </visual>
    <collision>
      <origin rpy="0 0 0" xyz="0 0 0"/>
      <geometry>
        <mesh filename="package://kortex_description/arms/gen3/7dof/meshes/shoulder_link.STL"/>
      </geometry>
    </collision>
  </link>
  <joint name="gopher/right_arm_joint_1" type="continuous">
    <origin rpy="3.1416 2.7629E-18 -4.9305E-36" xyz="0 0 0.15643"/>
    <parent link="gopher/right_arm_base_link"/>
    <child link="gopher/right_arm_shoulder_link"/>
    <axis xyz="0 0 1"/>
    <limit effort="39" velocity="1.3963"/>
  </joint>
  <link name="gopher/right_arm_half_arm_1_link">
    <inertial>
      <origin rpy="0 0 0" xyz="-4.4E-05 -0.09958 -0.013278"/>
      <mass value="1.1636"/>
      <inertia ixx="0.011088" ixy="5E-06" ixz="0" iyy="0.001072" iyz="-0.000691" izz="0.011255"/>
    </inertial>
    <visual>
      <origin rpy="0 0 0" xyz="0 0 0"/>
      <geometry>
        <mesh filename="package://kortex_description/arms/gen3/7dof/meshes/half_arm_1_link.STL"/>
      </geometry>
      <material name="">
        <color rgba="0.75294 0.75294 0.75294 1"/>
      </material>
    </visual>
    <collision>
      <origin rpy="0 0 0" xyz="0 0 0"/>
      <geometry>
        <mesh filename="package://kortex_description/arms/gen3/7dof/meshes/half_arm_1_link.STL"/>
      </geometry>
    </collision>
  </link>
  <joint name="gopher/right_arm_joint_2" type="revolute">
    <origin rpy="1.5708 2.1343E-17 -1.1102E-16" xyz="0 0.005375 -0.12838"/>
    <parent link="gopher/right_arm_shoulder_link"/>
    <child link="gopher/right_arm_half_arm_1_link"/>
    <axis xyz="0 0 1"/>
    <limit effort="39" lower="-2.41" upper="2.41" velocity="1.3963"/>
  </joint>
  <link name="gopher/right_arm_half_arm_2_link">
    <inertial>
      <origin rpy="0 0 0" xyz="-4.4E-05 -0.006641 -0.117892"/>
      <mass value="1.1636"/>
      <inertia ixx="0.010932" ixy="0" ixz="-7E-06" iyy="0.011127" iyz="0.000606" izz="0.001043"/>
    </inertial>
    <visual>
      <origin rpy="0 0 0" xyz="0 0 0"/>
      <geometry>
        <mesh filename="package://kortex_description/arms/gen3/7dof/meshes/half_arm_2_link.STL"/>
      </geometry>
      <material name="">
        <color rgba="0.75294 0.75294 0.75294 1"/>
      </material>
    </visual>
    <collision>
      <origin rpy="0 0 0" xyz="0 0 0"/>
      <geometry>
        <mesh filename="package://kortex_description/arms/gen3/7dof/meshes/half_arm_2_link.STL"/>
      </geometry>
    </collision>
  </link>
  <joint name="gopher/right_arm_joint_3" type="continuous">
    <origin rpy="-1.5708 1.2326E-32 -2.9122E-16" xyz="0 -0.21038 -0.006375"/>
    <parent link="gopher/right_arm_half_arm_1_link"/>
    <child link="gopher/right_arm_half_arm_2_link"/>
    <axis xyz="0 0 1"/>
    <limit effort="39" velocity="1.3963"/>
  </joint>
  <link name="gopher/right_arm_forearm_link">
    <inertial>
      <origin rpy="0 0 0" xyz="-1.8E-05 -0.075478 -0.015006"/>
      <mass value="0.9302"/>
      <inertia ixx="0.008147" ixy="-1E-06" ixz="0" iyy="0.000631" iyz="-0.0005" izz="0.008316"/>
    </inertial>
    <visual>
      <origin rpy="0 0 0" xyz="0 0 0"/>
      <geometry>
        <mesh filename="package://kortex_description/arms/gen3/7dof/meshes/forearm_link.STL"/>
      </geometry>
      <material name="">
        <color rgba="0.75294 0.75294 0.75294 1"/>
      </material>
    </visual>
    <collision>
      <origin rpy="0 0 0" xyz="0 0 0"/>
      <geometry>
        <mesh filename="package://kortex_description/arms/gen3/7dof/meshes/forearm_link.STL"/>
      </geometry>
    </collision>
  </link>
  <joint name="gopher/right_arm_joint_4" type="revolute">
    <origin rpy="1.5708 -6.6954E-17 -1.6653E-16" xyz="0 0.006375 -0.21038"/>
    <parent link="gopher/right_arm_half_arm_2_link"/>
    <child link="gopher/right_arm_forearm_link"/>
    <axis xyz="0 0 1"/>
    <limit effort="39" lower="-2.66" upper="2.66" velocity="1.3963"/>
  </joint>
  <link name="gopher/right_arm_spherical_wrist_1_link">
    <inertial>
      <origin rpy="0 0 0" xyz="1E-06 -0.009432 -0.063883"/>
      <mass value="0.6781"/>
      <inertia ixx="0.001596" ixy="0" ixz="0" iyy="0.001607" iyz="0.000256" izz="0.000399"/>
    </inertial>
    <visual>
      <origin rpy="0 0 0" xyz="0 0 0"/>
      <geometry>
        <mesh filename="package://kortex_description/arms/gen3/7dof/meshes/spherical_wrist_1_link.STL"/>
      </geometry>
      <material name="">
        <color rgba="0.75294 0.75294 0.75294 1"/>
      </material>
    </visual>
    <collision>
      <origin rpy="0 0 0" xyz="0 0 0"/>
      <geometry>
        <mesh filename="package://kortex_description/arms/gen3/7dof/meshes/spherical_wrist_1_link.STL"/>
      </geometry>
    </collision>
  </link>
  <joint name="gopher/right_arm_joint_5" type="continuous">
    <origin rpy="-1.5708 2.2204E-16 -6.373E-17" xyz="0 -0.20843 -0.006375"/>
    <parent link="gopher/right_arm_forearm_link"/>
    <child link="gopher/right_arm_spherical_wrist_1_link"/>
    <axis xyz="0 0 1"/>
    <limit effort="9" velocity="1.2218"/>
  </joint>
  <link name="gopher/right_arm_spherical_wrist_2_link">
    <inertial>
      <origin rpy="0 0 0" xyz="1E-06 -0.045483 -0.00965"/>
      <mass value="0.6781"/>
      <inertia ixx="0.001641" ixy="0" ixz="0" iyy="0.00041" iyz="-0.000278" izz="0.001641"/>
    </inertial>
    <visual>
      <origin rpy="0 0 0" xyz="0 0 0"/>
      <geometry>
        <mesh filename="package://kortex_description/arms/gen3/7dof/meshes/spherical_wrist_2_link.STL"/>
      </geometry>
      <material name="">
        <color rgba="0.75294 0.75294 0.75294 1"/>
      </material>
    </visual>
    <collision>
      <origin rpy="0 0 0" xyz="0 0 0"/>
      <geometry>
        <mesh filename="package://kortex_description/arms/gen3/7dof/meshes/spherical_wrist_2_link.STL"/>
      </geometry>
    </collision>
  </link>
  <joint name="gopher/right_arm_joint_6" type="revolute">
    <origin rpy="1.5708 9.2076E-28 -8.2157E-15" xyz="0 0.00017505 -0.10593"/>
    <parent link="gopher/right_arm_spherical_wrist_1_link"/>
    <child link="gopher/right_arm_spherical_wrist_2_link"/>
    <axis xyz="0 0 1"/>
    <limit effort="9" lower="-2.23" upper="2.23" velocity="1.2218"/>
  </joint>
  <link name="gopher/right_arm_bracelet_link">
    <inertial>
      <origin rpy="0 0 0" xyz="0.000281 0.011402 -0.029798"/>
      <mass value="0.5"/>
      <inertia ixx="0.000587" ixy="3E-06" ixz="3E-06" iyy="0.000369" iyz="-0.000118" izz="0.000609"/>
    </inertial>
    <visual>
      <origin rpy="0 0 0" xyz="0 0 0"/>
      <geometry>
        <mesh filename="package://kortex_description/arms/gen3/7dof/meshes/bracelet_with_vision_link.STL"/>
      </geometry>
      <material name="">
        <color rgba="0.75294 0.75294 0.75294 1"/>
      </material>
    </visual>
    <collision>
      <origin rpy="0 0 0" xyz="0 0 0"/>
      <geometry>
        <mesh filename="package://kortex_description/arms/gen3/7dof/meshes/bracelet_with_vision_link.STL"/>
      </geometry>
    </collision>
  </link>
  <joint name="gopher/right_arm_joint_7" type="continuous">
    <origin rpy="-1.5708 -5.5511E-17 9.6396E-17" xyz="0 -0.10593 -0.00017505"/>
    <parent link="gopher/right_arm_spherical_wrist_2_link"/>
    <child link="gopher/right_arm_bracelet_link"/>
    <axis xyz="0 0 1"/>
    <limit effort="9" velocity="1.2218"/>
  </joint>
  <link name="gopher/right_arm_end_effector_link">
    <inertial>
      <origin rpy="0 0 0" xyz="0 0 0"/>
      <mass value="0.001"/>
      <inertia ixx="1E-5" ixy="0" ixz="0" iyy="1E-5" iyz="-0" izz="1E-5"/>
    </inertial>
  </link>
  <joint name="gopher/right_arm_end_effector" type="fixed">
    <origin rpy="3.14159265358979 1.09937075168372E-32 0" xyz="0 0 -0.0615250000000001"/>
    <parent link="gopher/right_arm_bracelet_link"/>
    <child link="gopher/right_arm_end_effector_link"/>
    <axis xyz="0 0 0"/>
  </joint>
  <link name="gopher/right_arm_camera_link">
    <inertial>
      <origin rpy="0 0 0" xyz="0 0 0"/>
      <mass value="0.001"/>
      <inertia ixx="1E-5" ixy="0" ixz="0" iyy="1E-5" iyz="-0" izz="1E-5"/>
    </inertial>
  </link>
  <joint name="gopher/right_arm_camera_module" type="fixed">
    <origin rpy="3.14159265358979 3.14159265358979 0" xyz="0 0.05639 -0.00305"/>
    <parent link="gopher/right_arm_end_effector_link"/>
    <child link="gopher/right_arm_camera_link"/>
  </joint>
  <link name="gopher/right_arm_camera_depth_frame">
    <inertial>
      <origin rpy="0 0 0" xyz="0 0 0"/>
      <mass value="0.001"/>
      <inertia ixx="1E-5" ixy="0" ixz="0" iyy="1E-5" iyz="-0" izz="1E-5"/>
    </inertial>
  </link>
  <joint name="gopher/right_arm_depth_module" type="fixed">
    <origin rpy="3.14159265358979 3.14159265358979 0" xyz="0.0275 0.066 -0.00305"/>
    <parent link="gopher/right_arm_end_effector_link"/>
    <child link="gopher/right_arm_camera_depth_frame"/>
  </joint>
  <link name="gopher/right_arm_camera_color_frame">
    <inertial>
      <origin rpy="0 0 0" xyz="0 0 0"/>
      <mass value="0.001"/>
      <inertia ixx="1E-5" ixy="0" ixz="0" iyy="1E-5" iyz="-0" izz="1E-5"/>
    </inertial>
  </link>
  <joint name="gopher/right_arm_color_module" type="fixed">
    <origin rpy="3.14159265358979 3.14159265358979 0" xyz="0 0.05639 -0.00305"/>
    <parent link="gopher/right_arm_end_effector_link"/>
    <child link="gopher/right_arm_camera_color_frame"/>
  </joint>
  <!-- This line was removed by Kinova because we replaced the transmission file with our own 
    <xacro:include filename="$(find robotiq_2f_85_gripper_visualization)/urdf/robotiq_arg2f_transmission.xacro" /> -->
  <!-- Tool frame used by the arm -->
  <link name="gopher/right_arm_tool_frame">
    <inertial>
      <origin rpy="0 0 0" xyz="0 0 0"/>
      <mass value="0.001"/>
      <inertia ixx="1E-5" ixy="0" ixz="0" iyy="1E-5" iyz="-0" izz="1E-5"/>
    </inertial>
  </link>
  <joint name="gopher/right_arm_tool_frame_joint" type="fixed">
    <origin rpy="0 0 0" xyz="0 0 0.120"/>
    <parent link="gopher/right_arm_end_effector_link"/>
    <child link="gopher/right_arm_tool_frame"/>
    <axis xyz="0 0 0"/>
  </joint>
  <!-- This joint was added by Kinova -->
  <joint name="gopher/right_arm_gripper_base_joint" type="fixed">
    <parent link="gopher/right_arm_end_effector_link"/>
    <child link="gopher/right_arm_robotiq_arg2f_base_link"/>
    <origin rpy="0.0 0.0 1.57" xyz="0.0 0.0 0.0"/>
  </joint>
  <link name="gopher/right_arm_robotiq_arg2f_base_link">
    <inertial>
      <origin rpy="0 0 0" xyz="8.625E-08 -4.6583E-06 0.03145"/>
      <mass value="0.22652"/>
      <inertia ixx="0.00020005" ixy="-4.2442E-10" ixz="-2.9069E-10" iyy="0.00017832" iyz="-3.4402E-08" izz="0.00013478"/>
    </inertial>
    <visual>
      <origin rpy="0 0 0" xyz="0 0 0"/>
      <geometry>
        <mesh filename="package://kortex_description/grippers/robotiq_2f_85/meshes/collision/robotiq_arg2f_base_link.stl"/>
      </geometry>
      <material name="">
        <color rgba="0.1 0.1 0.1 1"/>
      </material>
    </visual>
    <collision>
      <origin rpy="0 0 0" xyz="0 0 0"/>
      <geometry>
        <mesh filename="package://kortex_description/grippers/robotiq_2f_85/meshes/collision/robotiq_arg2f_base_link.stl"/>
      </geometry>
    </collision>
  </link>
  <link name="gopher/right_arm_left_outer_knuckle">
    <inertial>
      <origin rpy="0 0 0" xyz="-0.000200000000003065 0.0199435877845359 0.0292245259211331"/>
      <mass value="0.00853198276973456"/>
      <inertia ixx="2.89328108496468E-06" ixy="-1.57935047237397E-19" ixz="-1.93980378593255E-19" iyy="1.86719750325683E-06" iyz="-1.21858577871576E-06" izz="1.21905238907251E-06"/>
    </inertial>
    <visual>
      <origin rpy="0 0 0" xyz="0 0 0"/>
      <geometry>
        <mesh filename="package://kortex_description/grippers/robotiq_2f_85/meshes/visual/robotiq_arg2f_85_outer_knuckle.dae" scale="0.001 0.001 0.001"/>
      </geometry>
      <material name="">
        <color rgba="0.792156862745098 0.819607843137255 0.933333333333333 1"/>
      </material>
    </visual>
    <collision>
      <origin rpy="0 0 0" xyz="0 0 0"/>
      <geometry>
        <mesh filename="package://kortex_description/grippers/robotiq_2f_85/meshes/collision/robotiq_arg2f_85_outer_knuckle.dae" scale="0.001 0.001 0.001"/>
      </geometry>
    </collision>
  </link>
  <link name="gopher/right_arm_left_outer_finger">
    <inertial>
      <origin rpy="0 0 0" xyz="0.00030115855001899 0.0373907951953854 -0.0208027427000385"/>
      <mass value="0.022614240507152"/>
      <inertia ixx="1.52518312458174E-05" ixy="9.76583423954399E-10" ixz="-5.43838577022588E-10" iyy="6.17694243867776E-06" iyz="6.78636130740228E-06" izz="1.16494917907219E-05"/>
    </inertial>
    <visual>
      <origin rpy="0 0 0" xyz="0 0 0"/>
      <geometry>
        <mesh filename="package://kortex_description/grippers/robotiq_2f_85/meshes/visual/robotiq_arg2f_85_outer_finger.dae" scale="0.001 0.001 0.001"/>
      </geometry>
      <material name="">
        <color rgba="0.1 0.1 0.1 1"/>
      </material>
    </visual>
    <collision>
      <origin rpy="0 0 0" xyz="0 0 0"/>
      <geometry>
        <mesh filename="package://kortex_description/grippers/robotiq_2f_85/meshes/collision/robotiq_arg2f_85_outer_finger.dae" scale="0.001 0.001 0.001"/>
      </geometry>
    </collision>
  </link>
  <link name="gopher/right_arm_left_inner_finger">
    <inertial>
      <origin rpy="0 0 0" xyz="0.000299999999999317 0.0160078233491243 -0.0136945669206257"/>
      <mass value="0.0104003125914103"/>
      <inertia ixx="2.71909453810972E-06" ixy="1.35402465472579E-21" ixz="-7.1817349065269E-22" iyy="7.69100314106116E-07" iyz="6.74715432769696E-07" izz="2.30315190420171E-06"/>
    </inertial>
    <visual>
      <origin rpy="0 0 0" xyz="0 0 0"/>
      <geometry>
        <mesh filename="package://kortex_description/grippers/robotiq_2f_85/meshes/visual/robotiq_arg2f_85_inner_finger.dae" scale="0.001 0.001 0.001"/>
      </geometry>
      <material name="">
        <color rgba="0.1 0.1 0.1 1"/>
      </material>
    </visual>
    <collision>
      <origin rpy="0 0 0" xyz="0 0 0"/>
      <geometry>
        <mesh filename="package://kortex_description/grippers/robotiq_2f_85/meshes/collision/robotiq_arg2f_85_inner_finger.dae" scale="0.001 0.001 0.001"/>
      </geometry>
    </collision>
  </link>
  <link name="gopher/right_arm_left_inner_finger_pad">
    <inertial>
      <origin rpy="0 0 0" xyz="0 0 0"/>
      <mass value="0.001"/>
      <inertia ixx="1E-5" ixy="0" ixz="0" iyy="1E-5" iyz="-0" izz="1E-5"/>
    </inertial>
    <visual>
      <origin rpy="0 0 0" xyz="0 0 0"/>
      <geometry>
        <box size="0.022 0.00635 0.0375"/>
      </geometry>
      <material name="">
        <color rgba="0.9 0.9 0.9 1"/>
      </material>
    </visual>
    <collision>
      <origin rpy="0 0 0" xyz="0 0 0"/>
      <geometry>
        <box size="0.022 0.00635 0.0375"/>
      </geometry>
      <material name="">
        <color rgba="0.9 0.0 0.0 1"/>
      </material>
    </collision>
  </link>
  <link name="gopher/right_arm_left_inner_knuckle">
    <inertial>
      <origin rpy="0 0 0" xyz="0.000123011831763771 0.0507850843201817 0.00103968640075166"/>
      <mass value="0.0271177346495152"/>
      <inertia ixx="2.61910379223783E-05" ixy="-2.43616858946494E-07" ixz="-6.37789906117123E-09" iyy="2.8270243746167E-06" iyz="-5.37200748039765E-07" izz="2.83695868220296E-05"/>
    </inertial>
    <visual>
      <origin rpy="0 0 0" xyz="0 0 0"/>
      <geometry>
        <mesh filename="package://kortex_description/grippers/robotiq_2f_85/meshes/visual/robotiq_arg2f_85_inner_knuckle.dae" scale="0.001 0.001 0.001"/>
      </geometry>
      <material name="">
        <color rgba="0.1 0.1 0.1 1"/>
      </material>
    </visual>
    <collision>
      <origin rpy="0 0 0" xyz="0 0 0"/>
      <geometry>
        <mesh filename="package://kortex_description/grippers/robotiq_2f_85/meshes/collision/robotiq_arg2f_85_inner_knuckle.dae" scale="0.001 0.001 0.001"/>
      </geometry>
    </collision>
  </link>
  <!-- Disable collision -->
  <disable_collision link1="gopher/right_arm_left_inner_knuckle" 
                     link2="gopher/right_arm_left_inner_finger"/>
  <link name="gopher/right_arm_right_outer_knuckle">
    <inertial>
      <origin rpy="0 0 0" xyz="-0.000200000000003065 0.0199435877845359 0.0292245259211331"/>
      <mass value="0.00853198276973456"/>
      <inertia ixx="2.89328108496468E-06" ixy="-1.57935047237397E-19" ixz="-1.93980378593255E-19" iyy="1.86719750325683E-06" iyz="-1.21858577871576E-06" izz="1.21905238907251E-06"/>
    </inertial>
    <visual>
      <origin rpy="0 0 0" xyz="0 0 0"/>
      <geometry>
        <mesh filename="package://kortex_description/grippers/robotiq_2f_85/meshes/visual/robotiq_arg2f_85_outer_knuckle.dae" scale="0.001 0.001 0.001"/>
      </geometry>
      <material name="">
        <color rgba="0.792156862745098 0.819607843137255 0.933333333333333 1"/>
      </material>
    </visual>
    <collision>
      <origin rpy="0 0 0" xyz="0 0 0"/>
      <geometry>
        <mesh filename="package://kortex_description/grippers/robotiq_2f_85/meshes/collision/robotiq_arg2f_85_outer_knuckle.dae" scale="0.001 0.001 0.001"/>
      </geometry>
    </collision>
  </link>
  <link name="gopher/right_arm_right_outer_finger">
    <inertial>
      <origin rpy="0 0 0" xyz="0.00030115855001899 0.0373907951953854 -0.0208027427000385"/>
      <mass value="0.022614240507152"/>
      <inertia ixx="1.52518312458174E-05" ixy="9.76583423954399E-10" ixz="-5.43838577022588E-10" iyy="6.17694243867776E-06" iyz="6.78636130740228E-06" izz="1.16494917907219E-05"/>
    </inertial>
    <visual>
      <origin rpy="0 0 0" xyz="0 0 0"/>
      <geometry>
        <mesh filename="package://kortex_description/grippers/robotiq_2f_85/meshes/visual/robotiq_arg2f_85_outer_finger.dae" scale="0.001 0.001 0.001"/>
      </geometry>
      <material name="">
        <color rgba="0.1 0.1 0.1 1"/>
      </material>
    </visual>
    <collision>
      <origin rpy="0 0 0" xyz="0 0 0"/>
      <geometry>
        <mesh filename="package://kortex_description/grippers/robotiq_2f_85/meshes/collision/robotiq_arg2f_85_outer_finger.dae" scale="0.001 0.001 0.001"/>
      </geometry>
    </collision>
  </link>
  <link name="gopher/right_arm_right_inner_finger">
    <inertial>
      <origin rpy="0 0 0" xyz="0.000299999999999317 0.0160078233491243 -0.0136945669206257"/>
      <mass value="0.0104003125914103"/>
      <inertia ixx="2.71909453810972E-06" ixy="1.35402465472579E-21" ixz="-7.1817349065269E-22" iyy="7.69100314106116E-07" iyz="6.74715432769696E-07" izz="2.30315190420171E-06"/>
    </inertial>
    <visual>
      <origin rpy="0 0 0" xyz="0 0 0"/>
      <geometry>
        <mesh filename="package://kortex_description/grippers/robotiq_2f_85/meshes/visual/robotiq_arg2f_85_inner_finger.dae" scale="0.001 0.001 0.001"/>
      </geometry>
      <material name="">
        <color rgba="0.1 0.1 0.1 1"/>
      </material>
    </visual>
    <collision>
      <origin rpy="0 0 0" xyz="0 0 0"/>
      <geometry>
        <mesh filename="package://kortex_description/grippers/robotiq_2f_85/meshes/collision/robotiq_arg2f_85_inner_finger.dae" scale="0.001 0.001 0.001"/>
      </geometry>
    </collision>
  </link>
  <link name="gopher/right_arm_right_inner_finger_pad">
    <inertial>
      <origin rpy="0 0 0" xyz="0 0 0"/>
      <mass value="0.001"/>
      <inertia ixx="1E-5" ixy="0" ixz="0" iyy="1E-5" iyz="-0" izz="1E-5"/>
    </inertial>
    <visual>
      <origin rpy="0 0 0" xyz="0 0 0"/>
      <geometry>
        <box size="0.022 0.00635 0.0375"/>
      </geometry>
      <material name="">
        <color rgba="0.9 0.9 0.9 1"/>
      </material>
    </visual>
    <collision>
      <origin rpy="0 0 0" xyz="0 0 0"/>
      <geometry>
        <box size="0.022 0.00635 0.0375"/>
      </geometry>
      <material name="">
        <color rgba="0.9 0.0 0.0 1"/>
      </material>
    </collision>
  </link>
  <link name="gopher/right_arm_right_inner_knuckle">
    <inertial>
      <origin rpy="0 0 0" xyz="0.000123011831763771 0.0507850843201817 0.00103968640075166"/>
      <mass value="0.0271177346495152"/>
      <inertia ixx="2.61910379223783E-05" ixy="-2.43616858946494E-07" ixz="-6.37789906117123E-09" iyy="2.8270243746167E-06" iyz="-5.37200748039765E-07" izz="2.83695868220296E-05"/>
    </inertial>
    <visual>
      <origin rpy="0 0 0" xyz="0 0 0"/>
      <geometry>
        <mesh filename="package://kortex_description/grippers/robotiq_2f_85/meshes/visual/robotiq_arg2f_85_inner_knuckle.dae" scale="0.001 0.001 0.001"/>
      </geometry>
      <material name="">
        <color rgba="0.1 0.1 0.1 1"/>
      </material>
    </visual>
    <collision>
      <origin rpy="0 0 0" xyz="0 0 0"/>
      <geometry>
        <mesh filename="package://kortex_description/grippers/robotiq_2f_85/meshes/collision/robotiq_arg2f_85_inner_knuckle.dae" scale="0.001 0.001 0.001"/>
      </geometry>
    </collision>
  </link>
  <!-- Disable collision -->
  <disable_collision link1="gopher/rihgt_arm_right_inner_knuckle" 
                     link2="kinova/right_arm_right_inner_finger"/>
  <joint name="gopher/right_arm_finger_joint" type="revolute">
    <origin rpy="0 0 3.14159265359" xyz="0 -0.0306011 0.054904"/>
    <parent link="gopher/right_arm_robotiq_arg2f_base_link"/>
    <child link="gopher/right_arm_left_outer_knuckle"/>
    <axis xyz="1 0 0"/>
    <limit effort="1000" lower="0" upper="0.8" velocity="2.0"/>
  </joint>
  <joint name="gopher/right_arm_left_outer_finger_joint" type="fixed">
    <origin rpy="0 0 0" xyz="0 0.0315 -0.0041"/>
    <parent link="gopher/right_arm_left_outer_knuckle"/>
    <child link="gopher/right_arm_left_outer_finger"/>
    <axis xyz="1 0 0"/>
  </joint>
  <joint name="gopher/right_arm_left_inner_knuckle_joint" type="revolute">
    <!-- <origin xyz="0 ${reflect * -0.0127} 0.06142" rpy="${pi / 2 + .725} 0 ${(reflect - 1) * pi / 2}" /> -->
    <origin rpy="0 0 3.14159265359" xyz="0 -0.0127 0.06142"/>
    <parent link="gopher/right_arm_robotiq_arg2f_base_link"/>
    <child link="gopher/right_arm_left_inner_knuckle"/>
    <axis xyz="1 0 0"/>
    <limit effort="1000" lower="0" upper="0.8757" velocity="2.0"/>
    <mimic joint="gopher/right_arm_finger_joint" multiplier="1" offset="0"/>
  </joint>
  <joint name="gopher/right_arm_left_inner_finger_joint" type="revolute">
    <origin rpy="0 0 0" xyz="0 0.0061 0.0471"/>
    <parent link="gopher/right_arm_left_outer_finger"/>
    <child link="gopher/right_arm_left_inner_finger"/>
    <axis xyz="1 0 0"/>
    <limit effort="1000" lower="-0.8757" upper="0.8757" velocity="2.0"/>
    <mimic joint="gopher/right_arm_finger_joint" multiplier="-1" offset="0"/>
  </joint>
  <joint name="gopher/right_arm_left_inner_finger_pad_joint" type="fixed">
    <origin rpy="0 0 0" xyz="0 -0.0220203446692936 0.03242"/>
    <parent link="gopher/right_arm_left_inner_finger"/>
    <child link="gopher/right_arm_left_inner_finger_pad"/>
    <axis xyz="0 0 1"/>
  </joint>
  <joint name="gopher/right_arm_right_outer_knuckle_joint" type="revolute">
    <origin rpy="0 0 0" xyz="0 0.0306011 0.054904"/>
    <parent link="gopher/right_arm_robotiq_arg2f_base_link"/>
    <child link="gopher/right_arm_right_outer_knuckle"/>
    <axis xyz="1 0 0"/>
    <limit effort="1000" lower="0" upper="0.81" velocity="2.0"/>
    <mimic joint="gopher/right_arm_finger_joint" multiplier="1" offset="0"/>
  </joint>
  <joint name="gopher/right_arm_right_outer_finger_joint" type="fixed">
    <origin rpy="0 0 0" xyz="0 0.0315 -0.0041"/>
    <parent link="gopher/right_arm_right_outer_knuckle"/>
    <child link="gopher/right_arm_right_outer_finger"/>
    <axis xyz="1 0 0"/>
  </joint>
  <joint name="gopher/right_arm_right_inner_knuckle_joint" type="revolute">
    <!-- <origin xyz="0 ${reflect * -0.0127} 0.06142" rpy="${pi / 2 + .725} 0 ${(reflect - 1) * pi / 2}" /> -->
    <origin rpy="0 0 0.0" xyz="0 0.0127 0.06142"/>
    <parent link="gopher/right_arm_robotiq_arg2f_base_link"/>
    <child link="gopher/right_arm_right_inner_knuckle"/>
    <axis xyz="1 0 0"/>
    <limit effort="1000" lower="0" upper="0.8757" velocity="2.0"/>
    <mimic joint="gopher/right_arm_finger_joint" multiplier="1" offset="0"/>
  </joint>
  <joint name="gopher/right_arm_right_inner_finger_joint" type="revolute">
    <origin rpy="0 0 0" xyz="0 0.0061 0.0471"/>
    <parent link="gopher/right_arm_right_outer_finger"/>
    <child link="gopher/right_arm_right_inner_finger"/>
    <axis xyz="1 0 0"/>
    <limit effort="1000" lower="-0.8757" upper="0.8757" velocity="2.0"/>
    <mimic joint="gopher/right_arm_finger_joint" multiplier="-1" offset="0"/>
  </joint>
  <joint name="gopher/right_arm_right_inner_finger_pad_joint" type="fixed">
    <origin rpy="0 0 0" xyz="0 -0.0220203446692936 0.03242"/>
    <parent link="gopher/right_arm_right_inner_finger"/>
    <child link="gopher/right_arm_right_inner_finger_pad"/>
    <axis xyz="0 0 1"/>
  </joint>
  <!-- Transmissions are loaded in the generic kortex xacro when simulation is enabled -->
  <!-- <xacro:robotiq_arg2f_transmission prefix="${prefix}"/> -->
  <!-- Run the macros -->
  <!-- Attach to parent link -->
  <joint name="gopher/left_arm_shoulder_to_arm_root" type="fixed">
    <child link="gopher/left_arm_base_link"/>
    <parent link="gopher/torso"/>
    <origin rpy="1.5708 0 3.1416" xyz="-0.03 0.03 0.7"/>
  </joint>
  <link name="gopher/left_arm_base_link">
    <inertial>
      <origin rpy="0 0 0" xyz="-0.000648 -0.000166 0.084487"/>
      <mass value="1.697"/>
      <inertia ixx="0.004622" ixy="9E-06" ixz="6E-05" iyy="0.004495" iyz="9E-06" izz="0.002079"/>
    </inertial>
    <visual>
      <origin rpy="0 0 0" xyz="0 0 0"/>
      <geometry>
        <mesh filename="package://kortex_description/arms/gen3/7dof/meshes/base_link.STL"/>
      </geometry>
      <material name="">
        <color rgba="0.75294 0.75294 0.75294 1"/>
      </material>
    </visual>
    <collision>
      <origin rpy="0 0 0" xyz="0 0 0"/>
      <geometry>
        <mesh filename="package://kortex_description/arms/gen3/7dof/meshes/base_link.STL"/>
      </geometry>
    </collision>
  </link>
  <link name="gopher/left_arm_shoulder_link">
    <inertial>
      <origin rpy="0 0 0" xyz="-2.3E-05 -0.010364 -0.07336"/>
      <mass value="1.3773"/>
      <inertia ixx="0.00457" ixy="1E-06" ixz="2E-06" iyy="0.004831" iyz="0.000448" izz="0.001409"/>
    </inertial>
    <visual>
      <origin rpy="0 0 0" xyz="0 0 0"/>
      <geometry>
        <mesh filename="package://kortex_description/arms/gen3/7dof/meshes/shoulder_link.STL"/>
      </geometry>
      <material name="">
        <color rgba="0.75294 0.75294 0.75294 1"/>
      </material>
    </visual>
    <collision>
      <origin rpy="0 0 0" xyz="0 0 0"/>
      <geometry>
        <mesh filename="package://kortex_description/arms/gen3/7dof/meshes/shoulder_link.STL"/>
      </geometry>
    </collision>
  </link>
  <joint name="gopher/left_arm_joint_1" type="continuous">
    <origin rpy="3.1416 2.7629E-18 -4.9305E-36" xyz="0 0 0.15643"/>
    <parent link="gopher/left_arm_base_link"/>
    <child link="gopher/left_arm_shoulder_link"/>
    <axis xyz="0 0 1"/>
    <limit effort="39" velocity="1.3963"/>
  </joint>
  <link name="gopher/left_arm_half_arm_1_link">
    <inertial>
      <origin rpy="0 0 0" xyz="-4.4E-05 -0.09958 -0.013278"/>
      <mass value="1.1636"/>
      <inertia ixx="0.011088" ixy="5E-06" ixz="0" iyy="0.001072" iyz="-0.000691" izz="0.011255"/>
    </inertial>
    <visual>
      <origin rpy="0 0 0" xyz="0 0 0"/>
      <geometry>
        <mesh filename="package://kortex_description/arms/gen3/7dof/meshes/half_arm_1_link.STL"/>
      </geometry>
      <material name="">
        <color rgba="0.75294 0.75294 0.75294 1"/>
      </material>
    </visual>
    <collision>
      <origin rpy="0 0 0" xyz="0 0 0"/>
      <geometry>
        <mesh filename="package://kortex_description/arms/gen3/7dof/meshes/half_arm_1_link.STL"/>
      </geometry>
    </collision>
  </link>
  <joint name="gopher/left_arm_joint_2" type="revolute">
    <origin rpy="1.5708 2.1343E-17 -1.1102E-16" xyz="0 0.005375 -0.12838"/>
    <parent link="gopher/left_arm_shoulder_link"/>
    <child link="gopher/left_arm_half_arm_1_link"/>
    <axis xyz="0 0 1"/>
    <limit effort="39" lower="-2.41" upper="2.41" velocity="1.3963"/>
  </joint>
  <link name="gopher/left_arm_half_arm_2_link">
    <inertial>
      <origin rpy="0 0 0" xyz="-4.4E-05 -0.006641 -0.117892"/>
      <mass value="1.1636"/>
      <inertia ixx="0.010932" ixy="0" ixz="-7E-06" iyy="0.011127" iyz="0.000606" izz="0.001043"/>
    </inertial>
    <visual>
      <origin rpy="0 0 0" xyz="0 0 0"/>
      <geometry>
        <mesh filename="package://kortex_description/arms/gen3/7dof/meshes/half_arm_2_link.STL"/>
      </geometry>
      <material name="">
        <color rgba="0.75294 0.75294 0.75294 1"/>
      </material>
    </visual>
    <collision>
      <origin rpy="0 0 0" xyz="0 0 0"/>
      <geometry>
        <mesh filename="package://kortex_description/arms/gen3/7dof/meshes/half_arm_2_link.STL"/>
      </geometry>
    </collision>
  </link>
  <joint name="gopher/left_arm_joint_3" type="continuous">
    <origin rpy="-1.5708 1.2326E-32 -2.9122E-16" xyz="0 -0.21038 -0.006375"/>
    <parent link="gopher/left_arm_half_arm_1_link"/>
    <child link="gopher/left_arm_half_arm_2_link"/>
    <axis xyz="0 0 1"/>
    <limit effort="39" velocity="1.3963"/>
  </joint>
  <link name="gopher/left_arm_forearm_link">
    <inertial>
      <origin rpy="0 0 0" xyz="-1.8E-05 -0.075478 -0.015006"/>
      <mass value="0.9302"/>
      <inertia ixx="0.008147" ixy="-1E-06" ixz="0" iyy="0.000631" iyz="-0.0005" izz="0.008316"/>
    </inertial>
    <visual>
      <origin rpy="0 0 0" xyz="0 0 0"/>
      <geometry>
        <mesh filename="package://kortex_description/arms/gen3/7dof/meshes/forearm_link.STL"/>
      </geometry>
      <material name="">
        <color rgba="0.75294 0.75294 0.75294 1"/>
      </material>
    </visual>
    <collision>
      <origin rpy="0 0 0" xyz="0 0 0"/>
      <geometry>
        <mesh filename="package://kortex_description/arms/gen3/7dof/meshes/forearm_link.STL"/>
      </geometry>
    </collision>
  </link>
  <joint name="gopher/left_arm_joint_4" type="revolute">
    <origin rpy="1.5708 -6.6954E-17 -1.6653E-16" xyz="0 0.006375 -0.21038"/>
    <parent link="gopher/left_arm_half_arm_2_link"/>
    <child link="gopher/left_arm_forearm_link"/>
    <axis xyz="0 0 1"/>
    <limit effort="39" lower="-2.66" upper="2.66" velocity="1.3963"/>
  </joint>
  <link name="gopher/left_arm_spherical_wrist_1_link">
    <inertial>
      <origin rpy="0 0 0" xyz="1E-06 -0.009432 -0.063883"/>
      <mass value="0.6781"/>
      <inertia ixx="0.001596" ixy="0" ixz="0" iyy="0.001607" iyz="0.000256" izz="0.000399"/>
    </inertial>
    <visual>
      <origin rpy="0 0 0" xyz="0 0 0"/>
      <geometry>
        <mesh filename="package://kortex_description/arms/gen3/7dof/meshes/spherical_wrist_1_link.STL"/>
      </geometry>
      <material name="">
        <color rgba="0.75294 0.75294 0.75294 1"/>
      </material>
    </visual>
    <collision>
      <origin rpy="0 0 0" xyz="0 0 0"/>
      <geometry>
        <mesh filename="package://kortex_description/arms/gen3/7dof/meshes/spherical_wrist_1_link.STL"/>
      </geometry>
    </collision>
  </link>
  <joint name="gopher/left_arm_joint_5" type="continuous">
    <origin rpy="-1.5708 2.2204E-16 -6.373E-17" xyz="0 -0.20843 -0.006375"/>
    <parent link="gopher/left_arm_forearm_link"/>
    <child link="gopher/left_arm_spherical_wrist_1_link"/>
    <axis xyz="0 0 1"/>
    <limit effort="9" velocity="1.2218"/>
  </joint>
  <link name="gopher/left_arm_spherical_wrist_2_link">
    <inertial>
      <origin rpy="0 0 0" xyz="1E-06 -0.045483 -0.00965"/>
      <mass value="0.6781"/>
      <inertia ixx="0.001641" ixy="0" ixz="0" iyy="0.00041" iyz="-0.000278" izz="0.001641"/>
    </inertial>
    <visual>
      <origin rpy="0 0 0" xyz="0 0 0"/>
      <geometry>
        <mesh filename="package://kortex_description/arms/gen3/7dof/meshes/spherical_wrist_2_link.STL"/>
      </geometry>
      <material name="">
        <color rgba="0.75294 0.75294 0.75294 1"/>
      </material>
    </visual>
    <collision>
      <origin rpy="0 0 0" xyz="0 0 0"/>
      <geometry>
        <mesh filename="package://kortex_description/arms/gen3/7dof/meshes/spherical_wrist_2_link.STL"/>
      </geometry>
    </collision>
  </link>
  <joint name="gopher/left_arm_joint_6" type="revolute">
    <origin rpy="1.5708 9.2076E-28 -8.2157E-15" xyz="0 0.00017505 -0.10593"/>
    <parent link="gopher/left_arm_spherical_wrist_1_link"/>
    <child link="gopher/left_arm_spherical_wrist_2_link"/>
    <axis xyz="0 0 1"/>
    <limit effort="9" lower="-2.23" upper="2.23" velocity="1.2218"/>
  </joint>
  <link name="gopher/left_arm_bracelet_link">
    <inertial>
      <origin rpy="0 0 0" xyz="0.000281 0.011402 -0.029798"/>
      <mass value="0.5"/>
      <inertia ixx="0.000587" ixy="3E-06" ixz="3E-06" iyy="0.000369" iyz="-0.000118" izz="0.000609"/>
    </inertial>
    <visual>
      <origin rpy="0 0 0" xyz="0 0 0"/>
      <geometry>
        <mesh filename="package://kortex_description/arms/gen3/7dof/meshes/bracelet_with_vision_link.STL"/>
      </geometry>
      <material name="">
        <color rgba="0.75294 0.75294 0.75294 1"/>
      </material>
    </visual>
    <collision>
      <origin rpy="0 0 0" xyz="0 0 0"/>
      <geometry>
        <mesh filename="package://kortex_description/arms/gen3/7dof/meshes/bracelet_with_vision_link.STL"/>
      </geometry>
    </collision>
  </link>
  <joint name="gopher/left_arm_joint_7" type="continuous">
    <origin rpy="-1.5708 -5.5511E-17 9.6396E-17" xyz="0 -0.10593 -0.00017505"/>
    <parent link="gopher/left_arm_spherical_wrist_2_link"/>
    <child link="gopher/left_arm_bracelet_link"/>
    <axis xyz="0 0 1"/>
    <limit effort="9" velocity="1.2218"/>
  </joint>
  <link name="gopher/left_arm_end_effector_link">
    <inertial>
      <origin rpy="0 0 0" xyz="0 0 0"/>
      <mass value="0.001"/>
      <inertia ixx="1E-5" ixy="0" ixz="0" iyy="1E-5" iyz="-0" izz="1E-5"/>
    </inertial>
  </link>
  <joint name="gopher/left_arm_end_effector" type="fixed">
    <origin rpy="3.14159265358979 1.09937075168372E-32 0" xyz="0 0 -0.0615250000000001"/>
    <parent link="gopher/left_arm_bracelet_link"/>
    <child link="gopher/left_arm_end_effector_link"/>
    <axis xyz="0 0 0"/>
  </joint>
  <link name="gopher/left_arm_camera_link">
    <inertial>
      <origin rpy="0 0 0" xyz="0 0 0"/>
      <mass value="0.001"/>
      <inertia ixx="1E-5" ixy="0" ixz="0" iyy="1E-5" iyz="-0" izz="1E-5"/>
    </inertial>
  </link>
  <joint name="gopher/left_arm_camera_module" type="fixed">
    <origin rpy="3.14159265358979 3.14159265358979 0" xyz="0 0.05639 -0.00305"/>
    <parent link="gopher/left_arm_end_effector_link"/>
    <child link="gopher/left_arm_camera_link"/>
  </joint>
  <link name="gopher/left_arm_camera_depth_frame">
    <inertial>
      <origin rpy="0 0 0" xyz="0 0 0"/>
      <mass value="0.001"/>
      <inertia ixx="1E-5" ixy="0" ixz="0" iyy="1E-5" iyz="-0" izz="1E-5"/>
    </inertial>
  </link>
  <joint name="gopher/left_arm_depth_module" type="fixed">
    <origin rpy="3.14159265358979 3.14159265358979 0" xyz="0.0275 0.066 -0.00305"/>
    <parent link="gopher/left_arm_end_effector_link"/>
    <child link="gopher/left_arm_camera_depth_frame"/>
  </joint>
  <link name="gopher/left_arm_camera_color_frame">
    <inertial>
      <origin rpy="0 0 0" xyz="0 0 0"/>
      <mass value="0.001"/>
      <inertia ixx="1E-5" ixy="0" ixz="0" iyy="1E-5" iyz="-0" izz="1E-5"/>
    </inertial>
  </link>
  <joint name="gopher/left_arm_color_module" type="fixed">
    <origin rpy="3.14159265358979 3.14159265358979 0" xyz="0 0.05639 -0.00305"/>
    <parent link="gopher/left_arm_end_effector_link"/>
    <child link="gopher/left_arm_camera_color_frame"/>
  </joint>
  <!-- This line was removed by Kinova because we replaced the transmission file with our own 
    <xacro:include filename="$(find robotiq_2f_85_gripper_visualization)/urdf/robotiq_arg2f_transmission.xacro" /> -->
  <!-- Tool frame used by the arm -->
  <link name="gopher/left_arm_tool_frame">
    <inertial>
      <origin rpy="0 0 0" xyz="0 0 0"/>
      <mass value="0.001"/>
      <inertia ixx="1E-5" ixy="0" ixz="0" iyy="1E-5" iyz="-0" izz="1E-5"/>
    </inertial>
  </link>
  <joint name="gopher/left_arm_tool_frame_joint" type="fixed">
    <origin rpy="0 0 0" xyz="0 0 0.120"/>
    <parent link="gopher/left_arm_end_effector_link"/>
    <child link="gopher/left_arm_tool_frame"/>
    <axis xyz="0 0 0"/>
  </joint>
  <!-- This joint was added by Kinova -->
  <joint name="gopher/left_arm_gripper_base_joint" type="fixed">
    <parent link="gopher/left_arm_end_effector_link"/>
    <child link="gopher/left_arm_robotiq_arg2f_base_link"/>
    <origin rpy="0.0 0.0 1.57" xyz="0.0 0.0 0.0"/>
  </joint>
  <link name="gopher/left_arm_robotiq_arg2f_base_link">
    <inertial>
      <origin rpy="0 0 0" xyz="8.625E-08 -4.6583E-06 0.03145"/>
      <mass value="0.22652"/>
      <inertia ixx="0.00020005" ixy="-4.2442E-10" ixz="-2.9069E-10" iyy="0.00017832" iyz="-3.4402E-08" izz="0.00013478"/>
    </inertial>
    <visual>
      <origin rpy="0 0 0" xyz="0 0 0"/>
      <geometry>
        <mesh filename="package://kortex_description/grippers/robotiq_2f_85/meshes/collision/robotiq_arg2f_base_link.stl"/>
      </geometry>
      <material name="">
        <color rgba="0.1 0.1 0.1 1"/>
      </material>
    </visual>
    <collision>
      <origin rpy="0 0 0" xyz="0 0 0"/>
      <geometry>
        <mesh filename="package://kortex_description/grippers/robotiq_2f_85/meshes/collision/robotiq_arg2f_base_link.stl"/>
      </geometry>
    </collision>
  </link>
  <link name="gopher/left_arm_left_outer_knuckle">
    <inertial>
      <origin rpy="0 0 0" xyz="-0.000200000000003065 0.0199435877845359 0.0292245259211331"/>
      <mass value="0.00853198276973456"/>
      <inertia ixx="2.89328108496468E-06" ixy="-1.57935047237397E-19" ixz="-1.93980378593255E-19" iyy="1.86719750325683E-06" iyz="-1.21858577871576E-06" izz="1.21905238907251E-06"/>
    </inertial>
    <visual>
      <origin rpy="0 0 0" xyz="0 0 0"/>
      <geometry>
        <mesh filename="package://kortex_description/grippers/robotiq_2f_85/meshes/visual/robotiq_arg2f_85_outer_knuckle.dae" scale="0.001 0.001 0.001"/>
      </geometry>
      <material name="">
        <color rgba="0.792156862745098 0.819607843137255 0.933333333333333 1"/>
      </material>
    </visual>
    <collision>
      <origin rpy="0 0 0" xyz="0 0 0"/>
      <geometry>
        <mesh filename="package://kortex_description/grippers/robotiq_2f_85/meshes/collision/robotiq_arg2f_85_outer_knuckle.dae" scale="0.001 0.001 0.001"/>
      </geometry>
    </collision>
  </link>
  <link name="gopher/left_arm_left_outer_finger">
    <inertial>
      <origin rpy="0 0 0" xyz="0.00030115855001899 0.0373907951953854 -0.0208027427000385"/>
      <mass value="0.022614240507152"/>
      <inertia ixx="1.52518312458174E-05" ixy="9.76583423954399E-10" ixz="-5.43838577022588E-10" iyy="6.17694243867776E-06" iyz="6.78636130740228E-06" izz="1.16494917907219E-05"/>
    </inertial>
    <visual>
      <origin rpy="0 0 0" xyz="0 0 0"/>
      <geometry>
        <mesh filename="package://kortex_description/grippers/robotiq_2f_85/meshes/visual/robotiq_arg2f_85_outer_finger.dae" scale="0.001 0.001 0.001"/>
      </geometry>
      <material name="">
        <color rgba="0.1 0.1 0.1 1"/>
      </material>
    </visual>
    <collision>
      <origin rpy="0 0 0" xyz="0 0 0"/>
      <geometry>
        <mesh filename="package://kortex_description/grippers/robotiq_2f_85/meshes/collision/robotiq_arg2f_85_outer_finger.dae" scale="0.001 0.001 0.001"/>
      </geometry>
    </collision>
  </link>
  <link name="gopher/left_arm_left_inner_finger">
    <inertial>
      <origin rpy="0 0 0" xyz="0.000299999999999317 0.0160078233491243 -0.0136945669206257"/>
      <mass value="0.0104003125914103"/>
      <inertia ixx="2.71909453810972E-06" ixy="1.35402465472579E-21" ixz="-7.1817349065269E-22" iyy="7.69100314106116E-07" iyz="6.74715432769696E-07" izz="2.30315190420171E-06"/>
    </inertial>
    <visual>
      <origin rpy="0 0 0" xyz="0 0 0"/>
      <geometry>
        <mesh filename="package://kortex_description/grippers/robotiq_2f_85/meshes/visual/robotiq_arg2f_85_inner_finger.dae" scale="0.001 0.001 0.001"/>
      </geometry>
      <material name="">
        <color rgba="0.1 0.1 0.1 1"/>
      </material>
    </visual>
    <collision>
      <origin rpy="0 0 0" xyz="0 0 0"/>
      <geometry>
        <mesh filename="package://kortex_description/grippers/robotiq_2f_85/meshes/collision/robotiq_arg2f_85_inner_finger.dae" scale="0.001 0.001 0.001"/>
      </geometry>
    </collision>
  </link>
  <link name="gopher/left_arm_left_inner_finger_pad">
    <inertial>
      <origin rpy="0 0 0" xyz="0 0 0"/>
      <mass value="0.001"/>
      <inertia ixx="1E-5" ixy="0" ixz="0" iyy="1E-5" iyz="-0" izz="1E-5"/>
    </inertial>
    <visual>
      <origin rpy="0 0 0" xyz="0 0 0"/>
      <geometry>
        <box size="0.022 0.00635 0.0375"/>
      </geometry>
      <material name="">
        <color rgba="0.9 0.9 0.9 1"/>
      </material>
    </visual>
    <collision>
      <origin rpy="0 0 0" xyz="0 0 0"/>
      <geometry>
        <box size="0.022 0.00635 0.0375"/>
      </geometry>
      <material name="">
        <color rgba="0.9 0.0 0.0 1"/>
      </material>
    </collision>
  </link>
  <link name="gopher/left_arm_left_inner_knuckle">
    <inertial>
      <origin rpy="0 0 0" xyz="0.000123011831763771 0.0507850843201817 0.00103968640075166"/>
      <mass value="0.0271177346495152"/>
      <inertia ixx="2.61910379223783E-05" ixy="-2.43616858946494E-07" ixz="-6.37789906117123E-09" iyy="2.8270243746167E-06" iyz="-5.37200748039765E-07" izz="2.83695868220296E-05"/>
    </inertial>
    <visual>
      <origin rpy="0 0 0" xyz="0 0 0"/>
      <geometry>
        <mesh filename="package://kortex_description/grippers/robotiq_2f_85/meshes/visual/robotiq_arg2f_85_inner_knuckle.dae" scale="0.001 0.001 0.001"/>
      </geometry>
      <material name="">
        <color rgba="0.1 0.1 0.1 1"/>
      </material>
    </visual>
    <collision>
      <origin rpy="0 0 0" xyz="0 0 0"/>
      <geometry>
        <mesh filename="package://kortex_description/grippers/robotiq_2f_85/meshes/collision/robotiq_arg2f_85_inner_knuckle.dae" scale="0.001 0.001 0.001"/>
      </geometry>
    </collision>
  </link>
  <!-- Disable collision -->
  <disable_collision link1="gopher/left_arm_left_inner_knuckle" 
                     link2="gopher/left_arm_left_inner_finger"/>
  <link name="gopher/left_arm_right_outer_knuckle">
    <inertial>
      <origin rpy="0 0 0" xyz="-0.000200000000003065 0.0199435877845359 0.0292245259211331"/>
      <mass value="0.00853198276973456"/>
      <inertia ixx="2.89328108496468E-06" ixy="-1.57935047237397E-19" ixz="-1.93980378593255E-19" iyy="1.86719750325683E-06" iyz="-1.21858577871576E-06" izz="1.21905238907251E-06"/>
    </inertial>
    <visual>
      <origin rpy="0 0 0" xyz="0 0 0"/>
      <geometry>
        <mesh filename="package://kortex_description/grippers/robotiq_2f_85/meshes/visual/robotiq_arg2f_85_outer_knuckle.dae" scale="0.001 0.001 0.001"/>
      </geometry>
      <material name="">
        <color rgba="0.792156862745098 0.819607843137255 0.933333333333333 1"/>
      </material>
    </visual>
    <collision>
      <origin rpy="0 0 0" xyz="0 0 0"/>
      <geometry>
        <mesh filename="package://kortex_description/grippers/robotiq_2f_85/meshes/collision/robotiq_arg2f_85_outer_knuckle.dae" scale="0.001 0.001 0.001"/>
      </geometry>
    </collision>
  </link>
  <link name="gopher/left_arm_right_outer_finger">
    <inertial>
      <origin rpy="0 0 0" xyz="0.00030115855001899 0.0373907951953854 -0.0208027427000385"/>
      <mass value="0.022614240507152"/>
      <inertia ixx="1.52518312458174E-05" ixy="9.76583423954399E-10" ixz="-5.43838577022588E-10" iyy="6.17694243867776E-06" iyz="6.78636130740228E-06" izz="1.16494917907219E-05"/>
    </inertial>
    <visual>
      <origin rpy="0 0 0" xyz="0 0 0"/>
      <geometry>
        <mesh filename="package://kortex_description/grippers/robotiq_2f_85/meshes/visual/robotiq_arg2f_85_outer_finger.dae" scale="0.001 0.001 0.001"/>
      </geometry>
      <material name="">
        <color rgba="0.1 0.1 0.1 1"/>
      </material>
    </visual>
    <collision>
      <origin rpy="0 0 0" xyz="0 0 0"/>
      <geometry>
        <mesh filename="package://kortex_description/grippers/robotiq_2f_85/meshes/collision/robotiq_arg2f_85_outer_finger.dae" scale="0.001 0.001 0.001"/>
      </geometry>
    </collision>
  </link>
  <link name="gopher/left_arm_right_inner_finger">
    <inertial>
      <origin rpy="0 0 0" xyz="0.000299999999999317 0.0160078233491243 -0.0136945669206257"/>
      <mass value="0.0104003125914103"/>
      <inertia ixx="2.71909453810972E-06" ixy="1.35402465472579E-21" ixz="-7.1817349065269E-22" iyy="7.69100314106116E-07" iyz="6.74715432769696E-07" izz="2.30315190420171E-06"/>
    </inertial>
    <visual>
      <origin rpy="0 0 0" xyz="0 0 0"/>
      <geometry>
        <mesh filename="package://kortex_description/grippers/robotiq_2f_85/meshes/visual/robotiq_arg2f_85_inner_finger.dae" scale="0.001 0.001 0.001"/>
      </geometry>
      <material name="">
        <color rgba="0.1 0.1 0.1 1"/>
      </material>
    </visual>
    <collision>
      <origin rpy="0 0 0" xyz="0 0 0"/>
      <geometry>
        <mesh filename="package://kortex_description/grippers/robotiq_2f_85/meshes/collision/robotiq_arg2f_85_inner_finger.dae" scale="0.001 0.001 0.001"/>
      </geometry>
    </collision>
  </link>
  <link name="gopher/left_arm_right_inner_finger_pad">
    <inertial>
      <origin rpy="0 0 0" xyz="0 0 0"/>
      <mass value="0.001"/>
      <inertia ixx="1E-5" ixy="0" ixz="0" iyy="1E-5" iyz="-0" izz="1E-5"/>
    </inertial>
    <visual>
      <origin rpy="0 0 0" xyz="0 0 0"/>
      <geometry>
        <box size="0.022 0.00635 0.0375"/>
      </geometry>
      <material name="">
        <color rgba="0.9 0.9 0.9 1"/>
      </material>
    </visual>
    <collision>
      <origin rpy="0 0 0" xyz="0 0 0"/>
      <geometry>
        <box size="0.022 0.00635 0.0375"/>
      </geometry>
      <material name="">
        <color rgba="0.9 0.0 0.0 1"/>
      </material>
    </collision>
  </link>
  <link name="gopher/left_arm_right_inner_knuckle">
    <inertial>
      <origin rpy="0 0 0" xyz="0.000123011831763771 0.0507850843201817 0.00103968640075166"/>
      <mass value="0.0271177346495152"/>
      <inertia ixx="2.61910379223783E-05" ixy="-2.43616858946494E-07" ixz="-6.37789906117123E-09" iyy="2.8270243746167E-06" iyz="-5.37200748039765E-07" izz="2.83695868220296E-05"/>
    </inertial>
    <visual>
      <origin rpy="0 0 0" xyz="0 0 0"/>
      <geometry>
        <mesh filename="package://kortex_description/grippers/robotiq_2f_85/meshes/visual/robotiq_arg2f_85_inner_knuckle.dae" scale="0.001 0.001 0.001"/>
      </geometry>
      <material name="">
        <color rgba="0.1 0.1 0.1 1"/>
      </material>
    </visual>
    <collision>
      <origin rpy="0 0 0" xyz="0 0 0"/>
      <geometry>
        <mesh filename="package://kortex_description/grippers/robotiq_2f_85/meshes/collision/robotiq_arg2f_85_inner_knuckle.dae" scale="0.001 0.001 0.001"/>
      </geometry>
    </collision>
  </link>
  <!-- Disable collision -->
  <disable_collision link1="gopher/left_arm_right_inner_knuckle" 
                     link2="gopher/left_arm_right_inner_finger"/>
  <joint name="gopher/left_arm_finger_joint" type="revolute">
    <origin rpy="0 0 3.14159265359" xyz="0 -0.0306011 0.054904"/>
    <parent link="gopher/left_arm_robotiq_arg2f_base_link"/>
    <child link="gopher/left_arm_left_outer_knuckle"/>
    <axis xyz="1 0 0"/>
    <limit effort="1000" lower="0" upper="0.8" velocity="2.0"/>
  </joint>
  <joint name="gopher/left_arm_left_outer_finger_joint" type="fixed">
    <origin rpy="0 0 0" xyz="0 0.0315 -0.0041"/>
    <parent link="gopher/left_arm_left_outer_knuckle"/>
    <child link="gopher/left_arm_left_outer_finger"/>
    <axis xyz="1 0 0"/>
  </joint>
  <joint name="gopher/left_arm_left_inner_knuckle_joint" type="revolute">
    <!-- <origin xyz="0 ${reflect * -0.0127} 0.06142" rpy="${pi / 2 + .725} 0 ${(reflect - 1) * pi / 2}" /> -->
    <origin rpy="0 0 3.14159265359" xyz="0 -0.0127 0.06142"/>
    <parent link="gopher/left_arm_robotiq_arg2f_base_link"/>
    <child link="gopher/left_arm_left_inner_knuckle"/>
    <axis xyz="1 0 0"/>
    <limit effort="1000" lower="0" upper="0.8757" velocity="2.0"/>
    <mimic joint="gopher/left_arm_finger_joint" multiplier="1" offset="0"/>
  </joint>
  <joint name="gopher/left_arm_left_inner_finger_joint" type="revolute">
    <origin rpy="0 0 0" xyz="0 0.0061 0.0471"/>
    <parent link="gopher/left_arm_left_outer_finger"/>
    <child link="gopher/left_arm_left_inner_finger"/>
    <axis xyz="1 0 0"/>
    <limit effort="1000" lower="-0.8757" upper="0.8757" velocity="2.0"/>
    <mimic joint="gopher/left_arm_finger_joint" multiplier="-1" offset="0"/>
  </joint>
  <joint name="gopher/left_arm_left_inner_finger_pad_joint" type="fixed">
    <origin rpy="0 0 0" xyz="0 -0.0220203446692936 0.03242"/>
    <parent link="gopher/left_arm_left_inner_finger"/>
    <child link="gopher/left_arm_left_inner_finger_pad"/>
    <axis xyz="0 0 1"/>
  </joint>
  <joint name="gopher/left_arm_right_outer_knuckle_joint" type="revolute">
    <origin rpy="0 0 0" xyz="0 0.0306011 0.054904"/>
    <parent link="gopher/left_arm_robotiq_arg2f_base_link"/>
    <child link="gopher/left_arm_right_outer_knuckle"/>
    <axis xyz="1 0 0"/>
    <limit effort="1000" lower="0" upper="0.81" velocity="2.0"/>
    <mimic joint="gopher/left_arm_finger_joint" multiplier="1" offset="0"/>
  </joint>
  <joint name="gopher/left_arm_right_outer_finger_joint" type="fixed">
    <origin rpy="0 0 0" xyz="0 0.0315 -0.0041"/>
    <parent link="gopher/left_arm_right_outer_knuckle"/>
    <child link="gopher/left_arm_right_outer_finger"/>
    <axis xyz="1 0 0"/>
  </joint>
  <joint name="gopher/left_arm_right_inner_knuckle_joint" type="revolute">
    <!-- <origin xyz="0 ${reflect * -0.0127} 0.06142" rpy="${pi / 2 + .725} 0 ${(reflect - 1) * pi / 2}" /> -->
    <origin rpy="0 0 0.0" xyz="0 0.0127 0.06142"/>
    <parent link="gopher/left_arm_robotiq_arg2f_base_link"/>
    <child link="gopher/left_arm_right_inner_knuckle"/>
    <axis xyz="1 0 0"/>
    <limit effort="1000" lower="0" upper="0.8757" velocity="2.0"/>
    <mimic joint="gopher/left_arm_finger_joint" multiplier="1" offset="0"/>
  </joint>
  <joint name="gopher/left_arm_right_inner_finger_joint" type="revolute">
    <origin rpy="0 0 0" xyz="0 0.0061 0.0471"/>
    <parent link="gopher/left_arm_right_outer_finger"/>
    <child link="gopher/left_arm_right_inner_finger"/>
    <axis xyz="1 0 0"/>
    <limit effort="1000" lower="-0.8757" upper="0.8757" velocity="2.0"/>
    <mimic joint="gopher/left_arm_finger_joint" multiplier="-1" offset="0"/>
  </joint>
  <joint name="gopher/left_arm_right_inner_finger_pad_joint" type="fixed">
    <origin rpy="0 0 0" xyz="0 -0.0220203446692936 0.03242"/>
    <parent link="gopher/left_arm_right_inner_finger"/>
    <child link="gopher/left_arm_right_inner_finger_pad"/>
    <axis xyz="0 0 1"/>
  </joint>
  <!-- Transmissions are loaded in the generic kortex xacro when simulation is enabled -->
  <!-- <xacro:robotiq_arg2f_transmission prefix="${prefix}"/> -->
</robot>
